Workbook
Name モジュールIF仕様_データ型: パラメータ!#REF!
Name モジュールIF仕様_増減: パラメータ!#REF!
Name 処理仕様_レイヤ: パラメータ!#REF!
Name 処理仕様_増減: パラメータ!#REF!

Sheet 表紙
T14: 第7.0.0版
T15: 46217

Sheet 改版履歴
A1: ドキュメント名 | U1: サブシステム名 | AO1: 版 | AQ1: 日付 | BA1: 作成者
A2: 帳票設計書（PC/スマデバ共通） | AO2: =VLOOKUP(10, 改版履歴!$K$8:$M$69, 1, 1) -> 7 | AQ2: 46217
A4: 改版履歴 | K4: 機能ID | U4: 機能名
A6: ※ 令和６年度以降の改版に関しては、修正が発生したシートのみ版数を上げることとする。
A7: 日付 | K7: 版数 | N7: 改版内容 | AV7: 作成者
A8: 43385 | K8: 0.1 | N8: 新規作成
A9: 43390 | K9: 0.2 | N9: XML出力イメージへの指摘（年調：画面コメント管理表_v05 .xlsx）に対応。
A10: 43397 | K10: 0.25 | N10: ﾚﾋﾞｭｰNo：VI18-000270の修正
A11: 43409 | K11: 0.3 | N11: 基礎控除申告書、所得金額調整控除申告書について追記。
A12: 43412 | K12: 0.35 | N12: VI18-000330を修正。
A13: 43446 | K13: 0.4 | N13: 帳票設計書に関するコメント管理表（No.1～31）を修正。
A14: 43501 | K14: 0.5 | N14: 帳票設計書に関するコメント管理表（No.32～61）を修正。
A15: 43529 | K15: 0.6 | N15: 帳票設計書に関するコメント管理表（No.62～66）を修正。
A16: 〃 | K16: 〃 | N16: 金額項目の修正（属性が数値となっている金額項目の属性を金額に、配置を右に変更） ※数値項目については検討の結果左詰めのままとする。
A17: 〃 | K17: 〃 | N17: 11_帳票項目定義のNo.30、33を数値から文字列に変更、印字フォーマットに「"最高"&999.9&"万円"」を追記
A18: 43656 | K18: 0.9 | N18: 基礎控除・配偶者控除・所得金額調整控除に様式イメージを反映 保険料控除に加工有無を追加 扶養控除等（異動）申告書のC障害者、寡婦、寡夫について最初の一人のみ詳細を記載する旨を追記 以下のレイアウトを2段組から1段組に変更 ・07_帳票レイアウト ・09_帳票レイアウト
A19: 43665 | K19: 0.95 | N19: 2019/6/28にお客様より入手した新帳票イメージに対応。 基礎控除申告書、配偶者控除、所得金額調整控除を1枚にまとめる。 ・15_帳票レイアウト ・15_帳票項目定義
A20: 〃 | K20: 〃 | N20: 以下のレイアウトを2段組から1段組に変更 ・11_帳票レイアウト
A21: 43766 | K21: 0.96 | N21: ・基礎控除申告書、配偶者控除、所得金額調整控除の統合を明記 ・繰り返し項目の明記
A22: 44099 | K22: 1 | N22: ・2019/10/28以降の変更箇所を反映 ・出力形式をA4横からA4縦に変更
A23: 44136 | K23: 1.1 | N23: ・各帳票の最新仕様を反映
A24: 44144 | K24: 1.1.2 | N24: ・住宅借入金等特別控除申告書について、最新仕様を反映
A25: 44530 | K25: 2 | N25: ・各帳票レイアウトから印マークの削除 ・07_帳票レイアウト、07_帳票項目定義の下記項目を削除 生計を一にする子の氏名 子の本年中の所得の見積額 生計を一にする子以外の扶養親族の氏名 扶養親族の本年中の所得の見積額 単身児童扶養者の関連項目 上記児童の令和２年の所得の見積額 ・15_帳票レイアウト、15_帳票項目定義の下記項目を追加・修正 あなたの本年中の給与所得金額の見積額 あなたの本年中の給与所得以外の所得金額の見積額 区分１ 区分２ ・11_帳票レイアウト、11_帳票レイアウトの下記項目を修正 項目①～⑧の文言修正
A26: 44707 | K26: 3 | N26: ・各帳票レイアウトの年分を修正 ・07_帳票レイアウト、07_帳票項目定義 の下記項目を削除 寡婦に該当する事実 ・07_帳票項目定義、08_帳票項目定義 の下記項目を追加 留学の有無 １年間の送金（予定）額
A27: 44721 | K27: 3 | N27: ・各帳票の項目名を修正 ・07_帳票レイアウト、08_帳票レイアウト、09_帳票レイアウト、15_帳票レイアウト ・07_帳票レイアウト、08_帳票レイアウト、09_帳票レイアウト、15_帳票レイアウト
A28: 44768 | K28: 3 | N28: ・09_帳票レイアウトの社会保険料の加工有無を追加 ・09_帳票項目定義の社会保険料の加工有無を追加
A29: 44817 | K29: 3 | N29: ・07_帳票レイアウト、07_帳票項目定義 の下記項目を追加 非居住者である扶養親族の該当する項目 源泉徴収される退職手当等に係る退職所得 一般の障害者 特別障害者 ひとり親・寡婦の区分 非居住者である親族/控除対象外国外扶養親族（控除対象外国外扶養親族から変更） ・07_帳票レイアウト、07_帳票項目定義 の下記項目を削除 留学の有無 １年間の送金（予定）額 ・08_帳票レイアウト、08_帳票項目定義 の下記項目を追加 非居住者である扶養親族の該当する項目 ・08_帳票レイアウト、08_帳票項目定義 の下記項目を削除 留学の有無 １年間の送金（予定）額 ・12_帳票レイアウト、12_帳票項目定義 の下記項目を追加 留学ビザ等書類 38万円以上の送金関係書類
A30: 44826 | K30: 3 | N30: ・07_帳票項目定義 下記項目の備考を追加 控除申告年分 帳票名 控除申告年分 所得の見積額 B控除対象扶養親族(16歳以上) ・08_帳票項目定義 下記項目の備考を追加 控除申告年分 帳票名 控除申告年分 所得の見積額 ・09_帳票項目定義 下記項目の備考を追加 控除申告年分 帳票名 地震保険料控除 加工有無 ・12_帳票項目定義 下記項目の備考を追加 控除申告年分 帳票名 ・15_帳票項目定義 下記項目の備考を追加 控除申告年分 帳票名
A31: 45048 | K31: 4 | N31: ・07_帳票項目定義 下記項目を追加 「申告書xml対応」列 ・08_帳票項目定義 下記項目を追加 「申告書xml対応」列 ・09_帳票項目定義 下記項目を追加 「申告書xml対応」列 ・11_帳票項目定義 下記項目を追加 「申告書xml対応」列 ➅特定増改築等の費用の額 ・12_帳票項目定義 下記項目を追加 「申告書xml対応」列 ・15_帳票項目定義 下記項目を追加 「申告書xml対応」列
A32: 45056 | K32: 4 | N32: ・サマリ 「表 作成対象申告書一覧」に下記を追加 16 控除額等一覧表 ・「16_帳票レイアウト」を追加 ・「16_帳票項目定義」を追加
A33: 45061 | K33: 4 | N33: ・「15_帳票項目定義」 「給与所得者の配偶者控除申告書 - 配偶者の個人番号」の属性を修正
A34: 45072 | K34: 4 | N34: ・「9_帳票レイアウト」 「小規模企業共済等掛金控除 - 加工有無」を追加したイメージレイアウトに修正 ・「9_帳票項目定義」 「小規模企業共済等掛金控除 - 加工有無」を追加
A35: 45072 | K35: 4 | N35: ・「15_帳票レイアウト」、「15_帳票項目定義」 基礎控除申告書 の内、「 あなたの本年中の合計所得の見積額」が2項目記載されていた内の片方を、「あなたの本年中の給与所得の見積額」に修正
A36: 45076 | K36: 4 | N36: ・「15_帳票レイアウト」 基礎控除申告書 の内、「 あなたの本年中の合計所得の見積額」が2項目記載されていた内の片方を、「あなたの本年中の給与所得の見積額」に修正（上記の修正漏れ対応）
... A77: 46217 | K77: 7 | N77: 12_帳票レイアウト 「住宅取得資金に係る借入金の年末残高等証明書」から「住宅取得資金に係る借入金の年末残高等証明書（調書方式を利用される場合は提出不要）」に変更 12_帳票項目定義 No.12の名称を「住宅取得資金に係る借入金の年末残高等証明書」から「住宅取得資金に係る借入金の年末残高等証明書（調書方式を利用される場合は提出不要）」に変更

Sheet サマリ
B2: 本設計書では以下の申告書に関して、出力項目の詳細を明確化する。
B4: 表 参考資料
B5: 項番 | C5: 資料名 | D5: 文書管理者 | E5: 備考
B6: 1 | C6: 別紙_PDF出力イメージ.xlsx
B9: 表 作成対象申告書一覧
B10: 項番 | C10: XMLデータ名
B11: 7 | C11: 給与所得者の扶養控除等（異動）申告書
B12: 8 | C12: 従たる給与についての扶養控除等（異動）申告書
B13: 9 | C13: 給与所得者の保険料控除申告書
B14: 10 | C14: 給与所得者の配偶者控除等申告書
B15: 11 | C15: 給与所得者の（特定増改築等）住宅借入金等特別控除申告書
B16: 12 | C16: 台紙
B17: 13 | C17: 基礎控除申告書
B18: 14 | C18: 所得金額調整控除申告書
B19: 15 | C19: 基礎控除申告書 兼 配偶者控除等申告書 兼 特定親族特別控除申告書 兼 所得金額調整控除申告書
B20: 16 | C20: 控除額等一覧表
B22: 表 帳票項目定義の属性の凡例
B23: 項番 | C23: 属性名 | D23: 凡例
B24: 1 | C24: 文字列 | D24: 2018年(平成29年)
B25: 2 | C25: 金額 | D25: 1000000000000
B26: 3 | C26: 全角文字列 | D26: あいうえお
B27: 4 | C27: 半角文字列 | D27: ｱｲｳｴｵ
B28: 5 | C28: 生年月日 | D28: 2018年(平成29年)10月10日
B29: 6 | C29: 日付 | D29: 43383
B30: 7 | C30: 年月日 | D30: 43383
B31: 8 | C31: 数値 | D31: 123
B33: 表 帳票項目定義のフォント名について
B34: 項番 | C34: OS | D34: 使用フォント
B35: 1 | C35: Windows | D35: MeiryoUI
B36: 2 | C36: MacOS | D36: ヒラギノ角ゴ ProN
B37: 3 | C37: iOS | D37: ヒラギノ角ゴ ProN
B38: 4 | C38: Android | D38: Noto Sans CJK

Sheet 07_帳票レイアウト
A1: ドキュメント名 | Y1: サブシステム名 | BI1: 版 | BK1: 日付 | BU1: 作成者
A2: =改版履歴!A2 -> 帳票設計書（PC/スマデバ共通） | BI2: 7 | BK2: 46184
A4: 帳票レイアウト | K4: 機能ID | Y4: 機能名 | AU4: 帳票ID | BI4: 帳票名
Y5: 扶養控除等（異動）申告書 | BI5: 扶養控除等（異動）申告書PDF
A6: 帳票資産名 | K6: 帳票項目仕様書ファイル名（拡張子は含まない） | AI6: 帳票レイアウト仕様書シート名 | BG6: 帳票フォームファイル名（拡張子は含まない）
A9: 帳票イメージ | AW9: 基本情報
AX11: サイズ | BB11: A4 | BF11: 方向 | BJ11: 縦 | BN11: 明細行数
AX12: 印字位置調整(mm) | BF12: X座標 | BJ12: 0 | BN12: Y座標 | BR12: 0
AX14: 罫線の印字枠 | BJ14: 可変方式
AX16: キー項目
AX17: キー番号 | BB17: 項目名 | BJ17: ソート | BN17: 改ページ | BR17: 合計レコード | BX17: ヘッダーレコード
AX34: 特記事項

Sheet 08_帳票レイアウト
A1: ドキュメント名 | Y1: サブシステム名 | BI1: 版 | BK1: 日付 | BU1: 作成者
A2: =改版履歴!A2 -> 帳票設計書（PC/スマデバ共通） | BI2: 7 | BK2: 46184
A4: 帳票レイアウト | K4: 機能ID | Y4: 機能名 | AU4: 帳票ID | BI4: 帳票名
Y5: 従たる給与についての扶養控除等（異動）申告書 | BI5: 従たる給与についての扶養控除等（異動）申告書PDF
A6: 帳票資産名 | K6: 帳票項目仕様書ファイル名（拡張子は含まない） | AI6: 帳票レイアウト仕様書シート名 | BG6: 帳票フォームファイル名（拡張子は含まない）
A9: 帳票イメージ | AW9: 基本情報
AX11: サイズ | BB11: A4 | BF11: 方向 | BJ11: 縦 | BN11: 明細行数
AX12: 印字位置調整(mm) | BF12: X座標 | BJ12: 0 | BN12: Y座標 | BR12: 0
AX14: 罫線の印字枠 | BJ14: 可変方式
AX16: キー項目
AX17: キー番号 | BB17: 項目名 | BJ17: ソート | BN17: 改ページ | BR17: 合計レコード | BX17: ヘッダーレコード
AX34: 特記事項

Sheet 09_帳票レイアウト
A1: ドキュメント名 | Y1: サブシステム名 | BI1: 版 | BK1: 日付 | BU1: 作成者
A2: =改版履歴!A2 -> 帳票設計書（PC/スマデバ共通） | BI2: 7 | BK2: 46183
A4: 帳票レイアウト | K4: 機能ID | Y4: 機能名 | AU4: 帳票ID | BI4: 帳票名
Y5: 保険料控除申告書 | BI5: 保険料控除申告書PDF
A6: 帳票資産名 | K6: 帳票項目仕様書ファイル名（拡張子は含まない） | AI6: 帳票レイアウト仕様書シート名 | BG6: 帳票フォームファイル名（拡張子は含まない）
A9: 帳票イメージ | AW9: 基本情報
AX11: サイズ | BB11: A4 | BF11: 方向 | BJ11: 縦 | BN11: 明細行数
AX12: 印字位置調整(mm) | BF12: X座標 | BJ12: 0 | BN12: Y座標 | BR12: 0
AX14: 罫線の印字枠 | BJ14: 可変方式
AX16: キー項目
AX17: キー番号 | BB17: 項目名 | BJ17: ソート | BN17: 改ページ | BR17: 合計レコード | BX17: ヘッダーレコード
AX34: 特記事項

Sheet 10_帳票レイアウト
A1: ドキュメント名 | Y1: サブシステム名 | BI1: 版 | BK1: 日付 | BU1: 作成者
A2: =改版履歴!A2 -> 帳票設計書（PC/スマデバ共通） | BI2: 1.1 | BK2: 44136
A4: 帳票レイアウト | K4: 機能ID | Y4: 機能名 | AU4: 帳票ID | BI4: 帳票名
Y5: 配偶者控除申告書 | BI5: 配偶者控除申告書PDF
A6: 帳票資産名 | K6: 帳票項目仕様書ファイル名（拡張子は含まない） | AI6: 帳票レイアウト仕様書シート名 | BG6: 帳票フォームファイル名（拡張子は含まない）
A9: 帳票イメージ | AW9: 基本情報
AX11: サイズ | BB11: A4 | BF11: 方向 | BJ11: 横 | BN11: 明細行数
AX12: 印字位置調整(mm) | BF12: X座標 | BJ12: 0 | BN12: Y座標 | BR12: 0
AX14: 罫線の印字枠 | BJ14: 可変方式
AX16: キー項目
AX17: キー番号 | BB17: 項目名 | BJ17: ソート | BN17: 改ページ | BR17: 合計レコード | BX17: ヘッダーレコード
AX34: 特記事項

Sheet 11_帳票レイアウト
A1: ドキュメント名 | Y1: サブシステム名 | BI1: 版 | BK1: 日付 | BU1: 作成者
A2: =改版履歴!A2 -> 帳票設計書（PC/スマデバ共通） | BI2: 7 | BK2: 46167
A4: 帳票レイアウト | K4: 機能ID | Y4: 機能名 | AU4: 帳票ID | BI4: 帳票名
Y5: 住宅借入金等特別控除申告書 | BI5: 住宅借入金等特別控除申告書PDF
A6: 帳票資産名 | K6: 帳票項目仕様書ファイル名（拡張子は含まない） | AI6: 帳票レイアウト仕様書シート名 | BG6: 帳票フォームファイル名（拡張子は含まない）
A9: 帳票イメージ | AW9: 基本情報
AX11: サイズ | BB11: A4 | BF11: 方向 | BJ11: 縦 | BN11: 明細行数
AX12: 印字位置調整(mm) | BF12: X座標 | BJ12: 0 | BN12: Y座標 | BR12: 0
AX14: 罫線の印字枠 | BJ14: 可変方式
AX16: キー項目
AX17: キー番号 | BB17: 項目名 | BJ17: ソート | BN17: 改ページ | BR17: 合計レコード | BX17: ヘッダーレコード
AX34: 特記事項

Sheet 12_帳票レイアウト
A1: ドキュメント名 | Y1: サブシステム名 | BI1: 版 | BK1: 日付 | BU1: 作成者
A2: =改版履歴!A2 -> 帳票設計書（PC/スマデバ共通） | BI2: 7 | BK2: 46217
A4: 帳票レイアウト | K4: 機能ID | Y4: 機能名 | AU4: 帳票ID | BI4: 帳票名
Y5: 共通機能 | BI5: 台紙PDF
A6: 帳票資産名 | K6: 帳票項目仕様書ファイル名（拡張子は含まない） | AI6: 帳票レイアウト仕様書シート名 | BG6: 帳票フォームファイル名（拡張子は含まない）
A9: 帳票イメージ | AW9: 基本情報
AX11: サイズ | BB11: A4 | BF11: 方向 | BJ11: 縦 | BN11: 明細行数
AX12: 印字位置調整(mm) | BF12: X座標 | BJ12: 0 | BN12: Y座標 | BR12: 0
AX14: 罫線の印字枠 | BJ14: 可変方式
AX16: キー項目
AX17: キー番号 | BB17: 項目名 | BJ17: ソート | BN17: 改ページ | BR17: 合計レコード | BX17: ヘッダーレコード
AX34: 特記事項

Sheet 13_帳票レイアウト
A1: ドキュメント名 | Y1: サブシステム名 | BI1: 版 | BK1: 日付 | BU1: 作成者
A2: =改版履歴!A2 -> 帳票設計書（PC/スマデバ共通） | BI2: 1.1 | BK2: 44136
A4: 帳票レイアウト | K4: 機能ID | Y4: 機能名 | AU4: 帳票ID | BI4: 帳票名
Y5: 基礎控除申告書 | BI5: 基礎控除申告書PDF
A6: 帳票資産名 | K6: 帳票項目仕様書ファイル名（拡張子は含まない） | AI6: 帳票レイアウト仕様書シート名 | BG6: 帳票フォームファイル名（拡張子は含まない）
A9: 帳票イメージ | AW9: 基本情報
AX11: サイズ | BB11: A4 | BF11: 方向 | BJ11: 横 | BN11: 明細行数
AX12: 印字位置調整(mm) | BF12: X座標 | BJ12: 0 | BN12: Y座標 | BR12: 0
AX14: 罫線の印字枠 | BJ14: 可変方式
AX16: キー項目
AX17: キー番号 | BB17: 項目名 | BJ17: ソート | BN17: 改ページ | BR17: 合計レコード | BX17: ヘッダーレコード
AX31: 特記事項

Sheet 14_帳票レイアウト
A1: ドキュメント名 | Y1: サブシステム名 | BI1: 版 | BK1: 日付 | BU1: 作成者
A2: =改版履歴!A2 -> 帳票設計書（PC/スマデバ共通） | BI2: =VLOOKUP(10, 改版履歴!$K$8:$M$47, 1, 1) -> 5 | BK2: =VLOOKUP(50000, 改版履歴!$A$8:$A$47, 1, 1) -> 45432
A4: 帳票レイアウト | K4: 機能ID | Y4: 機能名 | AU4: 帳票ID | BI4: 帳票名
Y5: 所得金額調整控除申告書 | BI5: 所得金額調整控除申告書PDF
A6: 帳票資産名 | K6: 帳票項目仕様書ファイル名（拡張子は含まない） | AI6: 帳票レイアウト仕様書シート名 | BG6: 帳票フォームファイル名（拡張子は含まない）
A9: 帳票イメージ | AW9: 基本情報
AX11: サイズ | BB11: A4 | BF11: 方向 | BJ11: 横 | BN11: 明細行数
AX12: 印字位置調整(mm) | BF12: X座標 | BJ12: 0 | BN12: Y座標 | BR12: 0
AX14: 罫線の印字枠 | BJ14: 可変方式
AX16: キー項目
AX17: キー番号 | BB17: 項目名 | BJ17: ソート | BN17: 改ページ | BR17: 合計レコード | BX17: ヘッダーレコード
AX34: 特記事項

Sheet 15_帳票レイアウト
A1: ドキュメント名 | Y1: サブシステム名 | BO1: 版 | BQ1: 日付 | CA1: 作成者
A2: =改版履歴!A2 -> 帳票設計書（PC/スマデバ共通） | BO2: 7 | BQ2: 46189
A4: 帳票レイアウト | K4: 機能ID | Y4: 機能名 | AU4: 帳票ID | BO4: 帳票名
Y5: 基礎控除申告書 兼 配偶者控除等申告書 兼 特定親族特別控除申告書 兼 所得金額調整控除申告書 | BO5: 基礎控除申告書 兼 配偶者控除等申告書 兼 特定親族特別控除申告書 兼 所得金額調整控除申告書PDF
A6: 帳票資産名 | K6: 帳票項目仕様書ファイル名（拡張子は含まない） | AI6: 帳票レイアウト仕様書シート名 | BM6: 帳票フォームファイル名（拡張子は含まない）
A9: 帳票イメージ | BC9: 基本情報
BD11: サイズ | BH11: A4 | BL11: 方向 | BP11: 縦 | BT11: 明細行数
BD12: 印字位置調整(mm) | BL12: X座標 | BP12: 0 | BT12: Y座標 | BX12: 0
BD14: 罫線の印字枠 | BP14: 可変方式
BD16: キー項目
BD17: キー番号 | BH17: 項目名 | BP17: ソート | BT17: 改ページ | BX17: 合計レコード | CD17: ヘッダーレコード
BD34: 特記事項

Sheet 16_帳票レイアウト
A1: ドキュメント名 | Y1: サブシステム名 | BI1: 版 | BK1: 日付 | BU1: 作成者
A2: =改版履歴!A2 -> 帳票設計書（PC/スマデバ共通） | BI2: 7 | BK2: 46167
A4: 帳票レイアウト | K4: 機能ID | Y4: 機能名 | AU4: 帳票ID | BI4: 帳票名
Y5: 控除額等一覧表PDF | BI5: 控除額等一覧表PDF
A6: 帳票資産名 | K6: 帳票項目仕様書ファイル名（拡張子は含まない） | AI6: 帳票レイアウト仕様書シート名 | BG6: 帳票フォームファイル名（拡張子は含まない）
A9: 帳票イメージ | AW9: 基本情報
AX11: サイズ | BB11: A4 | BF11: 方向 | BJ11: 縦 | BN11: 明細行数
AX12: 印字位置調整(mm) | BF12: X座標 | BJ12: 0 | BN12: Y座標 | BR12: 0
AX14: 罫線の印字枠 | BJ14: 可変方式
AX16: キー項目
AX17: キー番号 | BB17: 項目名 | BJ17: ソート | BN17: 改ページ | BR17: 合計レコード | BX17: ヘッダーレコード
AX34: 特記事項

Sheet 07_帳票項目定義
A1: ドキュメント名 | AH1: サブシステム名 | AO1: 版 | AP1: 日付 | AR1: 作成者
A2: =改版履歴!A2 -> 帳票設計書（PC/スマデバ共通） | AO2: 7 | AP2: 46167
A4: 帳票項目定義 | P4: 機能ID | AH4: 機能名 | AK4: 帳票ID | AO4: 帳票名
AH5: 扶養控除等（異動）申告書 | AO5: 扶養控除等（異動）申告書PDF
P6: 明細行数 | AH6: ファイルID | AK6: ファイル名
AH7: huyoukoujoPDF | AK7: 扶養控除等（異動）申告書PDFファイル
A9: No. | B9: 項目名 | T9: 項目ID | AH9: 属性 | AI9: 文字指定 | AM9: 数値編集 | AQ9: 導出項目 | AR9: キー項目 | AS9: 印字 フォーマット | AT9: 配置 | AU9: 編集内容 | AV9: 申告書xml対応 | AW9: 備考 | BR9: チェック日付 | CF9: 確認
AI10: フォント名 | AJ10: フォント サイズ | AK10: 表示 文字数 | AL10: 装飾 | AM10: カンマ 編集 | AN10: 小数点 (桁) | AO10: 0表示 | AP10: 符号 | AQ10: 符号 | BR10: 属性 | BS10: フォント名 | BT10: フォント サイズ | BU10: 表示 文字数 | BV10: 装飾 | BW10: カンマ 編集 | BX10: 小数点(桁) | BY10: 0表示 | BZ10: 符号 | CA10: 導出項目 | CB10: キー項目 | CC10: 印字 フォーマット | CD10: 配置 | CE10: 編集内容
A11: ヘッダ領域(H)
A12: 1 | B12: 控除申告年分 帳票名 | AH12: 全角文字列 | AI12: サマリ参照 | AJ12: 12 | AK12: 40 | AL12: 太字 | AT12: 左 | AV12: ※表側文言が可変 【令和Y年】 "令和Y年分 給与所得者の扶養控除等（異動）申告書" ※Yは和暦年 | AW12: 表示文言：年号Y年分 給与所得者の扶養控除等（異動）申告書
A13: 2 | B13: 所轄税務署 | AH13: 全角文字列 | AI13: サマリ参照 | AJ13: 12 | AK13: 10 | AL13: 太字 | AT13: 左 | AV13: xml001_B00050
A14: 3 | B14: 所轄市区町村 | AH14: 全角文字列 | AI14: サマリ参照 | AJ14: 12 | AK14: 10 | AL14: 太字 | AT14: 左 | AV14: xml001_B00060
A15: 4 | B15: フリガナ | AH15: 全角文字列 | AI15: サマリ参照 | AJ15: 10 | AK15: 60 | AT15: 左 | AV15: xml001_B00150
A16: 5 | B16: 氏名 | AH16: 全角文字列 | AI16: サマリ参照 | AJ16: 10 | AK16: 30 | AT16: 左 | AV16: xml001_B00160
A17: 6 | B17: ID（社員番号等） | AH17: 全角文字列 | AI17: サマリ参照 | AJ17: 10 | AK17: 15 | AT17: 左 | AV17: xml001_F00070
A18: 7
A19: 明細領域
A20: =ROW()-19 -> 1 | B20: 扶養親族等の数 | AH20: 数値 | AI20: サマリ参照 | AJ20: 10 | AK20: 2 | AT20: 左 | AV20: xml001_A00030
A21: =ROW()-19 -> 2 | B21: 提出及び本人に関する情報 | H21: 所轄税務署長等 | AH21: 全角文字列 | AI21: サマリ参照 | AJ21: 10 | AK21: 10 | AT21: 左 | AV21: xml001_B00050 xml001_B00060
A22: =ROW()-19 -> 3 | B22: 提出及び本人に関する情報 | H22: 給与の支払者の名称(氏名) | AH22: 全角文字列 | AI22: サマリ参照 | AJ22: 10 | AK22: 30 | AT22: 左 | AV22: xml001_B00080
A23: =ROW()-19 -> 4 | B23: 提出及び本人に関する情報 | H23: 給与の支払者の法人(個人)番号 | AH23: 数値 | AI23: サマリ参照 | AJ23: 10 | AK23: 13 | AT23: 左 | AV23: xml001_B00090
A24: =ROW()-19 -> 5 | B24: 提出及び本人に関する情報 | H24: 給与の支払者の所在地(住所) | AH24: 文字列 | AI24: サマリ参照 | AJ24: 10 | AK24: 100 | AT24: 左 | AV24: xml001_B00120 xml001_B00130 xml001_B00140
A25: =ROW()-19 -> 6 | B25: 提出及び本人に関する情報 | H25: (フリガナ) | AH25: 全角文字列 | AI25: サマリ参照 | AJ25: 10 | AK25: 60 | AT25: 左 | AV25: xml001_B00150
A26: =ROW()-19 -> 7 | B26: 提出及び本人に関する情報 | H26: あなたの氏名 | AH26: 全角文字列 | AI26: サマリ参照 | AJ26: 10 | AK26: 30 | AT26: 左 | AV26: xml001_B00160
A27: =ROW()-19 -> 8 | B27: 提出及び本人に関する情報 | H27: あなたの個人番号 | AH27: 数値 | AI27: サマリ参照 | AJ27: 10 | AK27: 12 | AT27: 左 | AV27: xml001_B00170
A28: =ROW()-19 -> 9 | B28: 提出及び本人に関する情報 | H28: 郵便番号 | AH28: 半角文字列 | AI28: サマリ参照 | AJ28: 10 | AK28: 8 | AT28: 左 | AV28: xml001_B00180
A29: =ROW()-19 -> 10 | B29: 提出及び本人に関する情報 | H29: あなたの住所又は居所 | AH29: 文字列 | AI29: サマリ参照 | AJ29: 10 | AK29: 100 | AT29: 左 | AV29: xml001_B00200 xml001_B00210 xml001_B00220
A30: =ROW()-19 -> 11 | B30: 提出及び本人に関する情報 | H30: あなたの生年月日 | AH30: 生年月日 | AI30: サマリ参照 | AJ30: 10 | AK30: 18 | AT30: 左 | AV30: xml001_B00240 xml001_B00250 xml001_B00260 xml001_B00270 xml001_B00280
A31: =ROW()-19 -> 12 | B31: 提出及び本人に関する情報 | H31: 世帯主の氏名 | AH31: 全角文字列 | AI31: サマリ参照 | AJ31: 10 | AK31: 30 | AT31: 左 | AV31: xml001_B00300
A32: =ROW()-19 -> 13 | B32: 提出及び本人に関する情報 | H32: あなたとの続柄 | AH32: 全角文字列 | AI32: サマリ参照 | AJ32: 10 | AK32: 10 | AT32: 左 | AV32: 【xml001_B00320がその他の時】 xml001_B00330 【それ以外】 xml001_B00320
... A34: =ROW()-19 -> 15 | B34: 提出及び本人に関する情報 | H34: 従たる給与についての 扶養控除等申告書の提出 | AH34: 全角文字列 | AI34: サマリ参照 | AJ34: 10 | AK34: 2 | AT34: 左 | AV34: xml001_B00340
A35: =ROW()-19 -> 16 | B35: 提出及び本人に関する情報 | H35: 一般の障害者 | N35: 本人 | AH35: 全角文字列 | AI35: サマリ参照 | AJ35: 10 | AK35: 3 | AT35: 右 | AV35: xml001_B00370
A36: =ROW()-19 -> 17 | B36: 提出及び本人に関する情報 | H36: 特別障害者 | N36: 本人 | AH36: 全角文字列 | AI36: サマリ参照 | AJ36: 10 | AK36: 3 | AT36: 右 | AV36: xml001_B00370
A37: =ROW()-19 -> 18 | B37: 提出及び本人に関する情報 | H37: 手帳の種類 | N37: 本人 | AH37: 全角文字列 | AI37: サマリ参照 | AJ37: 10 | AK37: 20 | AT37: 左 | AV37: xml001_B00380
A38: =ROW()-19 -> 19 | B38: 提出及び本人に関する情報 | H38: 交付年月日 | N38: 本人 | AH38: 年月日 | AI38: サマリ参照 | AJ38: 10 | AK38: 18 | AT38: 左 | AV38: xml001_B00382 xml001_B00383 xml001_B00384
A39: =ROW()-19 -> 20 | B39: 提出及び本人に関する情報 | H39: 異動月日 | N39: 本人 | AH39: 年月日 | AI39: サマリ参照 | AJ39: 10 | AK39: 18 | AT39: 左 | AV39: xml001_B00410 xml001_B00420
A40: =ROW()-19 -> 21 | B40: 提出及び本人に関する情報 | H40: 異動事由 | N40: 本人 | AH40: 全角文字列 | AI40: サマリ参照 | AJ40: 10 | AK40: 50 | AT40: 左 | AV40: 【xml001_B00440がその他の時】 xml001_B00450 【それ以外】 xml001_B00440
A41: =ROW()-19 -> 22 | B41: 提出及び本人に関する情報 | H41: 障害者又は勤労学生の内容 | N41: 本人 | AH41: 全角文字列 | AI41: サマリ参照 | AJ41: 10 | AK41: 50 | AT41: 左 | AV41: xml001_B00460
A42: =ROW()-19 -> 23 | B42: 提出及び本人に関する情報 | H42: 寡婦・ひとり親等の区分 | N42: 本人 | AH42: 全角文字列 | AI42: サマリ参照 | AJ42: 10 | AK42: 3 | AT42: 左 | AV42: xml001_B00480
A43: =ROW()-19 -> 24 | B43: 提出及び本人に関する情報 | H43: 異動月日 | N43: 本人 | AH43: 日付 | AI43: サマリ参照 | AJ43: 10 | AK43: 6 | AT43: 左 | AV43: xml001_B00540 xml001_B00550
...

Sheet 08_帳票項目定義
A1: ドキュメント名 | AH1: サブシステム名 | AO1: 版 | AP1: 日付 | AR1: 作成者
A2: =改版履歴!A2 -> 帳票設計書（PC/スマデバ共通） | AO2: 7 | AP2: 46167
A4: 帳票項目定義 | P4: 機能ID | AH4: 機能名 | AK4: 帳票ID | AO4: 帳票名
AH5: 従たる給与についての扶養控除等（異動）申告書 | AO5: 給与についての扶養控除等（異動）申告書PDF
P6: 明細行数 | AH6: ファイルID | AK6: ファイル名
AH7: huyoukoujosubPDF | AK7: 従たる給与についての扶養控除等（異動）申告書PDFファイル
A9: No. | B9: 項目名 | T9: 項目ID | AH9: 属性 | AI9: 文字指定 | AM9: 数値編集 | AQ9: 導出項目 | AR9: キー項目 | AS9: 印字 フォーマット | AT9: 配置 | AU9: 編集内容 | AV9: 申告書xml対応 | AW9: 備考 | BR9: チェック日付 | CF9: 確認
AI10: フォント名 | AJ10: フォント サイズ | AK10: 表示 文字数 | AL10: 装飾 | AM10: カンマ 編集 | AN10: 小数点 (桁) | AO10: 0表示 | AP10: 符号 | AQ10: 符号 | BR10: 属性 | BS10: フォント名 | BT10: フォント サイズ | BU10: 表示 文字数 | BV10: 装飾 | BW10: カンマ 編集 | BX10: 小数点(桁) | BY10: 0表示 | BZ10: 符号 | CA10: 導出項目 | CB10: キー項目 | CC10: 印字 フォーマット | CD10: 配置 | CE10: 編集内容
A11: ヘッダ領域(H)
A12: 1 | B12: 控除申告年分 帳票名 | AH12: 全角文字列 | AI12: サマリ参照 | AJ12: 12 | AK12: 40 | AL12: 太字 | AT12: 左 | AV12: ※表側文言が可変 【令和Y年】 "令和Y年分 従たる給与についての扶養控除等(異動)申告書" ※Yは和暦年 | AW12: 表示文言：年号Y年分 従たる給与についての扶養控除等（異動）申告書
A13: 2 | B13: 所轄税務署 | AH13: 全角文字列 | AI13: サマリ参照 | AJ13: 12 | AK13: 10 | AL13: 太字 | AT13: 左 | AV13: xml002_B00050
A14: 3 | B14: フリガナ | AH14: 全角文字列 | AI14: サマリ参照 | AJ14: 10 | AK14: 60 | AT14: 左 | AV14: xml002_B00140
A15: 4 | B15: 氏名 | AH15: 全角文字列 | AI15: サマリ参照 | AJ15: 10 | AK15: 30 | AT15: 左 | AV15: xml002_B00150
A16: 5 | B16: ID（社員番号等） | AH16: 全角文字列 | AI16: サマリ参照 | AJ16: 10 | AK16: 15 | AT16: 左 | AV16: xml002_F00070
A17: 6
A18: 明細領域
A19: 1 | B19: 提出に関する情報 | H19: 所轄税務署長 | AH19: 全角文字列 | AI19: サマリ参照 | AJ19: 10 | AK19: 10 | AT19: 左 | AV19: xml002_B00050
A20: 2 | B20: 提出に関する情報 | H20: 給与の支払者の名称(氏名) | AH20: 全角文字列 | AI20: サマリ参照 | AJ20: 10 | AK20: 30 | AT20: 左 | AV20: xml002_B00070
A21: 3 | B21: 提出に関する情報 | H21: 給与の支払者の法人(個人)番号 | AH21: 数値 | AI21: サマリ参照 | AJ21: 10 | AK21: 13 | AT21: 左 | AV21: xml002_B00080
A22: 4 | B22: 提出に関する情報 | H22: 給与の支払者の所在地(住所) | AH22: 文字列 | AI22: サマリ参照 | AJ22: 10 | AK22: 100 | AT22: 左 | AV22: xml002_B00110 xml002_B00120 xml002_B00130
A23: 5 | B23: 提出に関する情報 | H23: (フリガナ) | AH23: 全角文字列 | AI23: サマリ参照 | AJ23: 10 | AK23: 60 | AT23: 左 | AV23: xml002_B00140
A24: 6 | B24: 提出に関する情報 | H24: あなたの氏名 | AH24: 全角文字列 | AI24: サマリ参照 | AJ24: 10 | AK24: 30 | AT24: 左 | AV24: xml002_B00150
A25: 7 | B25: 提出に関する情報 | H25: あなたの個人番号 | AH25: 数値 | AI25: サマリ参照 | AJ25: 10 | AK25: 12 | AT25: 左 | AV25: xml002_B00160
A26: 8 | B26: 提出に関する情報 | H26: 郵便番号 | AH26: 半角文字列 | AI26: サマリ参照 | AJ26: 10 | AK26: 8 | AT26: 左 | AV26: xml002_B00170
A27: 9 | B27: 提出に関する情報 | H27: あなたの住所又は居所 | AH27: 文字列 | AI27: サマリ参照 | AJ27: 10 | AK27: 100 | AT27: 左 | AV27: xml002_B00190 xml002_B00200 xml002_B00210
A28: 10 | B28: 提出に関する情報 | H28: あなたの生年月日 | AH28: 生年月日 | AI28: サマリ参照 | AJ28: 10 | AK28: 18 | AT28: 左 | AV28: xml002_B00230 xml002_B00240 xml002_B00250 xml002_B00260 xml002_B00270
A29: 11 | B29: 提出に関する情報 | H29: 世帯主の氏名 | AH29: 全角文字列 | AI29: サマリ参照 | AJ29: 10 | AK29: 30 | AT29: 左 | AV29: xml002_B00290
A30: 12 | B30: 提出に関する情報 | H30: あなたとの続柄 | AH30: 全角文字列 | AI30: サマリ参照 | AJ30: 10 | AK30: 10 | AT30: 左 | AV30: 【xml002_B00310がその他の時】 xml002_B00320 【それ以外】 xml002_B00310
A31: 13 | B31: A主たる給与の見積額等 | H31: 主たる給与の支払者の名称（氏名） | AH31: 全角文字列 | AI31: サマリ参照 | AJ31: 10 | AK31: 30 | AT31: 左 | AV31: xml002_C00010
A32: 14 | B32: A主たる給与の見積額等 | H32: 左の給与の支払者から受ける控除申告年中の給与の収入金額の見積額① | AH32: 金額 | AI32: サマリ参照 | AJ32: 10 | AK32: 10 | AM32: ○ | AO32: ○ | AT32: 右 | AV32: xml002_C00020 | AW32: 表示文言：左の給与の支払者から受ける元号Y年中の給与の収入金額の見積額①
A33: 15 | B33: A主たる給与の見積額等 | H33: ①の給与に対する給与所得控除後の金額② | AH33: 金額 | AI33: サマリ参照 | AJ33: 10 | AK33: 10 | AM33: ○ | AO33: ○ | AT33: 右 | AV33: xml002_C00030
A34: 16 | B34: A主たる給与の見積額等 | H34: ①の給与から控除される社会保険料等の見積額③ | AH34: 金額 | AI34: サマリ参照 | AJ34: 10 | AK34: 10 | AM34: ○ | AO34: ○ | AT34: 右 | AV34: xml002_C00040
A35: 17 | B35: A主たる給与の見積額等 | H35: あなたが控除を受けられる配偶者（特別）控除額、扶養控除額、特定親族特別控除額、基礎控除額及び障害者等の控除額の合計額④ | AH35: 金額 | AI35: サマリ参照 | AJ35: 10 | AK35: 10 | AM35: ○ | AO35: ○ | AT35: 右 | AV35: xml002_C00050
A36: 18 | B36: Bこの給与から控除を受ける源泉控除対象配偶者又は源泉控除対象親族 | H36: (フリガナ) | AH36: 全角文字列 | AI36: サマリ参照 | AJ36: 10 | AK36: 60 | AT36: 左 | AV36: xml002_D00010 | AW36: 0～20件の繰り返し項目
A37: 19 | B37: Bこの給与から控除を受ける源泉控除対象配偶者又は源泉控除対象親族 | H37: 氏名 | AH37: 全角文字列 | AI37: サマリ参照 | AJ37: 10 | AK37: 30 | AT37: 左 | AV37: xml002_D00020 | AW37: 0～20件の繰り返し項目
A38: 20 | B38: Bこの給与から控除を受ける源泉控除対象配偶者又は源泉控除対象親族 | H38: 個人番号 | AH38: 数値 | AI38: サマリ参照 | AJ38: 10 | AK38: 12 | AT38: 左 | AV38: xml002_D00030 | AW38: 0～20件の繰り返し項目
A39: 21 | B39: Bこの給与から控除を受ける源泉控除対象配偶者又は源泉控除対象親族 | H39: あなたとの続柄 | AH39: 全角文字列 | AI39: サマリ参照 | AJ39: 10 | AK39: 10 | AT39: 左 | AV39: 【xml002_D00050がその他の時】 xml002_D00060 【それ以外】 xml002_D00050 | AW39: 0～20件の繰り返し項目
A40: 22 | B40: Bこの給与から控除を受ける源泉控除対象配偶者又は源泉控除対象親族 | H40: 生年月日 | AH40: 生年月日 | AI40: サマリ参照 | AJ40: 10 | AK40: 18 | AT40: 左 | AV40: xml002_D00080 xml002_D00090 xml002_D00100 xml002_D00110 xml002_D00120 | AW40: 0～20件の繰り返し項目
A41: 23 | B41: Bこの給与から控除を受ける源泉控除対象配偶者又は源泉控除対象親族 | H41: 控除申告年分 所得の見積額 | AH41: 金額 | AI41: サマリ参照 | AJ41: 10 | AK41: 7 | AM41: ○ | AO41: ○ | AT41: 右 | AV41: xml002_D00130 | AW41: 0～20件の繰り返し項目 表示文言：年号Y年中の所得の見積額
A42: 24 | B42: Bこの給与から控除を受ける源泉控除対象配偶者又は源泉控除対象親族 | H42: 非居住者である親族 | AH42: 全角文字列 | AI42: サマリ参照 | AJ42: 10 | AK42: 3 | AT42: 左 | AV42: xml002_D00140 | AW42: 0～20件の繰り返し項目
...

Sheet 09_帳票項目定義
A1: ドキュメント名 | AH1: サブシステム名 | AO1: 版 | AP1: 日付 | AR1: 作成者
A2: =改版履歴!A2 -> 帳票設計書（PC/スマデバ共通） | AO2: 7 | AP2: 46183
A4: 帳票項目定義 | P4: 機能ID | AH4: 機能名 | AK4: 帳票ID | AO4: 帳票名
AH5: 保険料控除申告書 | AO5: 保険料控除申告書PDF
P6: 明細行数 | AH6: ファイルID | AK6: ファイル名
AH7: hokenkoujoPDF | AK7: 保険料控除申告書PDFファイル
A9: No. | B9: 項目名 | T9: 項目ID | AH9: 属性 | AI9: 文字指定 | AM9: 数値編集 | AQ9: 導出項目 | AR9: キー項目 | AS9: 印字 フォーマット | AT9: 配置 | AU9: 編集内容 | AV9: 申告書xml対応 | AW9: 備考 | BR9: チェック日付 | CF9: 確認
AI10: フォント名 | AJ10: フォント サイズ | AK10: 表示 文字数 | AL10: 装飾 | AM10: カンマ 編集 | AN10: 小数点 (桁) | AO10: 0表示 | AP10: 符号 | AQ10: 符号 | BR10: 属性 | BS10: フォント名 | BT10: フォント サイズ | BU10: 表示 文字数 | BV10: 装飾 | BW10: カンマ 編集 | BX10: 小数点(桁) | BY10: 0表示 | BZ10: 符号 | CA10: 導出項目 | CB10: キー項目 | CC10: 印字 フォーマット | CD10: 配置 | CE10: 編集内容
A11: ヘッダ領域(H)
A12: 1 | B12: 控除申告年分 帳票名 | AH12: 全角文字列 | AI12: サマリ参照 | AJ12: 12 | AK12: 40 | AL12: 太字 | AT12: 左 | AV12: ※表側文言が可変 【令和Y年】 "令和Y年分 給与所得者の保険料控除申告書" ※Yは和暦年 | AW12: 表示文言：年号Y年分 給与所得者の保険料控除申告書
A13: 2 | B13: 所轄税務署 | AH13: 全角文字列 | AI13: サマリ参照 | AJ13: 12 | AK13: 10 | AL13: 太字 | AT13: 左 | AV13: xml003_B00050
A14: 3 | B14: フリガナ | AH14: 全角文字列 | AI14: サマリ参照 | AJ14: 10 | AK14: 60 | AT14: 左 | AV14: xml003_B00140
A15: 4 | B15: 氏名 | AH15: 全角文字列 | AI15: サマリ参照 | AJ15: 10 | AK15: 30 | AT15: 左 | AV15: xml003_B00150
A16: 5 | B16: ID（社員番号等） | AH16: 全角文字列 | AI16: サマリ参照 | AJ16: 10 | AK16: 15 | AT16: 左 | AV16: xml003_J00070
A17: 6
A18: 7
A19: 明細領域
A20: 1 | B20: 提出に関する情報 | H20: 所轄税務署長 | AH20: 全角文字列 | AI20: サマリ参照 | AJ20: 10 | AK20: 10 | AT20: 左 | AV20: xml003_B00050
A21: 2 | B21: 提出に関する情報 | H21: 給与の支払者の名称(氏名) | AH21: 全角文字列 | AI21: サマリ参照 | AJ21: 10 | AK21: 30 | AT21: 左 | AV21: xml003_B00070
A22: 3 | B22: 提出に関する情報 | H22: 給与の支払者の法人番号 | AH22: 数値 | AI22: サマリ参照 | AJ22: 10 | AK22: 13 | AT22: 左 | AV22: xml003_B00080
A23: 4 | B23: 提出に関する情報 | H23: 給与の支払者の所在地(住所) | AH23: 文字列 | AI23: サマリ参照 | AJ23: 10 | AK23: 100 | AT23: 左 | AV23: xml003_B00110 xml003_B00120 xml003_B00130
A24: 5 | B24: 提出に関する情報 | H24: (フリガナ) | AH24: 全角文字列 | AI24: サマリ参照 | AJ24: 10 | AK24: 60 | AT24: 左 | AV24: xml003_B00140
A25: 6 | B25: 提出に関する情報 | H25: あなたの氏名 | AH25: 全角文字列 | AI25: サマリ参照 | AJ25: 10 | AK25: 30 | AT25: 左 | AV25: xml003_B00150
A26: 7 | B26: 提出に関する情報 | H26: あなたの住所又は居所 | AH26: 文字列 | AI26: サマリ参照 | AJ26: 10 | AK26: 100 | AT26: 左 | AV26: xml003_B00180 xml003_B00190 xml003_B00200
A27: 8 | B27: 一般の生命保険料 | H27: 保険会社等の名称 | AH27: 全角文字列 | AI27: サマリ参照 | AJ27: 10 | AK27: 30 | AT27: 左 | AV27: xml003_C00020 | AW27: 0～20件の繰り返し項目
A28: 9 | B28: 一般の生命保険料 | H28: 保険等の種類 | AH28: 全角文字列 | AI28: サマリ参照 | AJ28: 10 | AK28: 30 | AT28: 左 | AV28: xml003_C00040 | AW28: 0～20件の繰り返し項目
A29: 10 | B29: 一般の生命保険料 | H29: 保険期間又は年金支払期間 | AH29: 文字列 | AI29: サマリ参照 | AJ29: 10 | AK29: 3 | AT29: 左 | AV29: xml003_C00060 | AW29: 0～20件の繰り返し項目 0：終身 1：1年以下 2～99：N年
A30: 11 | B30: 一般の生命保険料 | H30: 保険等の契約者の氏名 | AH30: 全角文字列 | AI30: サマリ参照 | AJ30: 10 | AK30: 100 | AT30: 左 | AV30: xml003_C00070 | AW30: 0～20件の繰り返し項目
A31: 12 | B31: 一般の生命保険料 | H31: 受取人 | AH31: 全角文字列 | AI31: サマリ参照 | AJ31: 10 | AK31: 40 | AT31: 左 | AV31: 【xml003_C00100がその他の時】 xml003_C00080 xml003_C00100 【それ以外】 xml003_C00080 xml003_C00110 | AW31: 0～20件の繰り返し項目
A32: 13 | B32: 一般の生命保険料 | H32: 新・旧の区分 | AH32: 全角文字列 | AI32: サマリ参照 | AJ32: 10 | AK32: 1 | AT32: 左 | AV32: xml003_C00120 | AW32: 0～20件の繰り返し項目
A33: 14 | B33: 一般の生命保険料 | H33: あなたが本年中に支払った保険料等の金額(分配を受けた余剰金等の控除後の金額)(a) | AH33: 金額 | AI33: サマリ参照 | AJ33: 10 | AK33: 15 | AM33: ○ | AO33: ○ | AT33: 右 | AV33: xml003_C00130 | AW33: 0～20件の繰り返し項目
A34: 15 | B34: 一般の生命保険料 | H34: 加工有無 | AH34: 全角文字列 | AI34: サマリ参照 | AJ34: 10 | AK34: 15 | AT34: 左 | AV34: xml003_C00131 | AW34: 0. 初期値 1. 証明書：読込・有（修正・無） 契約：個人 2. 証明書：読込・有（修正・有） 契約：個人 3. 証明書：読込・無 契約：個人 4. 証明書：読込・無 契約：団体
A35: 16 | B35: 一般の生命保険料 | H35: (a)のうち新保険料等の金額の合計額 | AH35: 金額 | AI35: サマリ参照 | AJ35: 10 | AK35: 15 | AM35: ○ | AO35: ○ | AT35: 右 | AV35: xml003_C00140
A36: 17 | B36: 一般の生命保険料 | H36: 年齢23歳未満の扶養親族の有無 | AH36: 全角文字列 | AI36: サマリ参照 | AJ36: 10 | AK36: 2 | AT36: 左 | AV36: xml003_C00170
A37: 18 | B37: 一般の生命保険料 | H37: (フリガナ) | AH37: 全角文字列 | AI37: サマリ参照 | AJ37: 10 | AK37: 60 | AT37: 左 | AV37: xml003_C00171
A38: 19 | B38: 一般の生命保険料 | H38: 年齢23歳未満の扶養親族の氏名 | AH38: 全角文字列 | AI38: サマリ参照 | AJ38: 10 | AK38: 30 | AT38: 左 | AV38: xml003_C00172
A39: 20 | B39: 一般の生命保険料 | H39: 左記の者の個人番号 | AH39: 数値 | AI39: サマリ参照 | AJ39: 10 | AK39: 12 | AT39: 左 | AV39: xml003_C00174
A40: 21 | B40: 一般の生命保険料 | H40: 左記の者のあなたとの続柄 | AH40: 全角文字列 | AI40: サマリ参照 | AJ40: 10 | AK40: 10 | AT40: 左 | AV40: 【xml003_C00188がその他の時】 xml003_C00189 【それ以外】 xml003_C00188
A41: 22 | B41: 一般の生命保険料 | H41: 左記の者の生年月日 | AH41: 生年月日 | AI41: サマリ参照 | AJ41: 10 | AK41: 18 | AT41: 左 | AV41: xml003_C00176 xml003_C00177 xml003_C00178 xml003_C00179 xml003_C00180
A42: 23 | B42: 一般の生命保険料 | H42: あなたと左記の者の住所又は居所が異なる場合の左記の者の住所又は居所 | AH42: 全角文字列 | AI42: サマリ参照 | AJ42: 10 | AK42: 100 | AT42: 左 | AV42: xml003_C00182 xml003_C00183 xml003_C00184 xml003_C00185 xml003_C00186
...

Sheet 10_帳票項目定義
A1: ドキュメント名 | AH1: サブシステム名 | AO1: 版 | AP1: 日付 | AR1: 作成者
A2: =改版履歴!A2 -> 帳票設計書（PC/スマデバ共通） | AO2: 4 | AP2: 45218
A4: 帳票項目定義 | P4: 機能ID | AH4: 機能名 | AK4: 帳票ID | AO4: 帳票名
AH5: 配偶者控除申告書 | AO5: 配偶者控除申告書PDF
P6: 明細行数 | AH6: ファイルID | AK6: ファイル名
AH7: haigusyakoujoPDF | AK7: 配偶者控除申告書PDFファイル
A9: No. | B9: 項目名 | T9: 項目ID | AH9: 属性 | AI9: 文字指定 | AM9: 数値編集 | AQ9: 導出項目 | AR9: キー項目 | AS9: 印字 フォーマット | AT9: 配置 | AU9: 編集内容 | AV9: 備考 | BQ9: チェック日付 | CE9: 確認
AI10: フォント名 | AJ10: フォント サイズ | AK10: 表示 文字数 | AL10: 装飾 | AM10: カンマ 編集 | AN10: 小数点 (桁) | AO10: 0表示 | AP10: 符号 | AQ10: 符号 | BQ10: 属性 | BR10: フォント名 | BS10: フォント サイズ | BT10: 表示 文字数 | BU10: 装飾 | BV10: カンマ 編集 | BW10: 小数点(桁) | BX10: 0表示 | BY10: 符号 | BZ10: 導出項目 | CA10: キー項目 | CB10: 印字 フォーマット | CC10: 配置 | CD10: 編集内容
A11: ヘッダ領域(H)
A12: 1 | B12: 控除申告年分 帳票名 | AH12: 全角文字列 | AI12: サマリ参照 | AJ12: 12 | AK12: 40 | AL12: 太字 | AT12: 左
A13: 2 | B13: 所轄税務署 | AH13: 全角文字列 | AI13: サマリ参照 | AJ13: 12 | AK13: 10 | AL13: 太字 | AT13: 左
A14: 3 | B14: フリガナ | AH14: 全角文字列 | AI14: サマリ参照 | AJ14: 10 | AK14: 60 | AT14: 左
A15: 4 | B15: 氏名 | AH15: 全角文字列 | AI15: サマリ参照 | AJ15: 10 | AK15: 30 | AT15: 左
A16: 5 | B16: ID（社員番号等） | AH16: 全角文字列 | AI16: サマリ参照 | AJ16: 10 | AK16: 15 | AT16: 左
A17: 6
A18: 7
A19: 出力領域
A20: 1 | B20: 提出に関する情報 | H20: 給与の支払者の名称 | AH20: 全角文字列 | AI20: サマリ参照 | AJ20: 10 | AK20: 30 | AT20: 左
A21: 2 | B21: 提出に関する情報 | H21: 給与の支払者の法人番号 | AH21: 数値 | AI21: サマリ参照 | AJ21: 10 | AK21: 13 | AT21: 左
A22: 3 | B22: 提出に関する情報 | H22: 給与の支払者の所在地 | AH22: 文字列 | AI22: サマリ参照 | AJ22: 10 | AK22: 100 | AT22: 左
A23: 4 | B23: 提出に関する情報 | H23: フリガナ | AH23: 全角文字列 | AI23: サマリ参照 | AJ23: 10 | AK23: 60 | AT23: 左
A24: 5 | B24: 提出に関する情報 | H24: 氏名 | AH24: 全角文字列 | AI24: サマリ参照 | AJ24: 10 | AK24: 30 | AT24: 左
A25: 6 | B25: 提出に関する情報 | H25: 住所又は居所 | AH25: 文字列 | AI25: サマリ参照 | AJ25: 10 | AK25: 100 | AT25: 左
A26: 7 | B26: 合計所得の見積額 | H26: あなたの本年中の合計所得金額の見積額 | AH26: 金額 | AI26: サマリ参照 | AJ26: 10 | AK26: 15 | AM26: ○ | AO26: ○ | AT26: 右
A27: 8 | B27: 合計所得の見積額 | H27: 区分１ | AH27: 文字列 | AI27: サマリ参照 | AJ27: 10 | AK27: 16 | AT27: 左
A28: 9 | B28: 配偶者 | H28: フリガナ | AH28: 全角文字列 | AI28: サマリ参照 | AJ28: 10 | AK28: 60 | AT28: 左
A29: 10 | B29: 配偶者 | H29: 氏名 | AH29: 全角文字列 | AI29: サマリ参照 | AJ29: 10 | AK29: 30 | AT29: 左
A30: 11 | B30: 配偶者 | H30: 個人番号 | AH30: 数値 | AI30: サマリ参照 | AJ30: 10 | AK30: 12 | AT30: 左
A31: 12 | B31: 配偶者 | H31: 生年月日 | AH31: 生年月日 | AI31: サマリ参照 | AJ31: 10 | AK31: 18 | AT31: 左
A32: 13 | B32: 配偶者 | H32: 住所又は居所 | AH32: 全角文字列 | AI32: サマリ参照 | AJ32: 10 | AK32: 100 | AT32: 左
A33: 14 | B33: 配偶者 | H33: 老人控除対象配偶者 | AH33: 全角文字列 | AI33: サマリ参照 | AJ33: 10 | AK33: 3 | AT33: 左
A34: 15 | B34: 配偶者 | H34: 非居住者である配偶者 | AH34: 全角文字列 | AI34: サマリ参照 | AJ34: 10 | AK34: 3 | AT34: 左
A35: 16 | B35: 配偶者 | H35: 生計を一にする事実 | AH35: 金額 | AI35: サマリ参照 | AJ35: 10 | AK35: 100 | AT35: 右
A36: 17 | B36: 配偶者 | H36: 配偶者の本年中の合計所得金額の見積額 | AH36: 金額 | AI36: サマリ参照 | AJ36: 10 | AK36: 9 | AM36: ○ | AO36: ○ | AT36: 右
A37: 18 | B37: 配偶者 | H37: 区分２ | AH37: 文字列 | AI37: サマリ参照 | AJ37: 10 | AK37: 30 | AT37: 左
A38: 19 | B38: 控除の計算 | H38: 配偶者控除の額 | AH38: 金額 | AI38: サマリ参照 | AJ38: 10 | AK38: 7 | AL38: 太字 | AM38: ○ | AO38: ○ | AT38: 右
A39: 20 | B39: 控除の計算 | H39: 配偶者特別控除の額 | AH39: 金額 | AI39: サマリ参照 | AJ39: 10 | AK39: 7 | AL39: 太字 | AM39: ○ | AO39: ○ | AT39: 右
A40: 21 | B40: 参考情報 | H40: 提出年月日 | AH40: 年月日 | AI40: サマリ参照 | AJ40: 10 | AK40: 18 | AT40: 左
A41: 22 | B41: 参考情報 | H41: ID（社員番号等） | AH41: 文字列 | AI41: サマリ参照 | AJ41: 10 | AK41: 15 | AT41: 左
A42: フッター領域(F)
...

Sheet 11_帳票項目定義
A1: ドキュメント名 | AH1: サブシステム名 | AO1: 版 | AP1: 日付 | AR1: 作成者
A2: =改版履歴!A2 -> 帳票設計書（PC/スマデバ共通） | AO2: 7 | AP2: 46175
A4: 帳票項目定義 | P4: 機能ID | AH4: 機能名 | AK4: 帳票ID | AO4: 帳票名
AH5: 住宅借入金等特別控除申告書 | AO5: 住宅借入金等特別控除申告書PDF
P6: 明細行数 | AH6: ファイルID | AK6: ファイル名
AH7: jutakukoujoPDF | AK7: 住宅借入金等特別控除申告書PDFファイル
A9: No. | B9: 項目名 | T9: 項目ID | AH9: 属性 | AI9: 文字指定 | AM9: 数値編集 | AQ9: 導出項目 | AR9: キー項目 | AS9: 印字 フォーマット | AT9: 配置 | AU9: 編集内容 | AV9: 申告書xml対応 | AW9: 備考 | BR9: チェック日付 | CF9: 確認
AI10: フォント名 | AJ10: フォント サイズ | AK10: 表示 文字数 | AL10: 装飾 | AM10: カンマ 編集 | AN10: 小数点 (桁) | AO10: 0表示 | AP10: 符号 | AQ10: 符号 | BR10: 属性 | BS10: フォント名 | BT10: フォント サイズ | BU10: 表示 文字数 | BV10: 装飾 | BW10: カンマ 編集 | BX10: 小数点(桁) | BY10: 0表示 | BZ10: 符号 | CA10: 導出項目 | CB10: キー項目 | CC10: 印字 フォーマット | CD10: 配置 | CE10: 編集内容
A11: ヘッダ領域(H)
A12: 1 | B12: 控除申告年分 帳票名 | AH12: 全角文字列 | AI12: サマリ参照 | AJ12: 12 | AK12: 40 | AL12: 太字 | AT12: 左 | AV12: xml005_B00030 xml005_B00040
A13: 2 | B13: 所轄税務署 | AH13: 全角文字列 | AI13: サマリ参照 | AJ13: 12 | AK13: 10 | AL13: 太字 | AT13: 左 | AV13: xml005_B00050
A14: 3 | B14: フリガナ | AH14: 全角文字列 | AI14: サマリ参照 | AJ14: 10 | AK14: 60 | AT14: 左 | AV14: xml005_B00140
A15: 4 | B15: 氏名 | AH15: 全角文字列 | AI15: サマリ参照 | AJ15: 10 | AK15: 30 | AT15: 左 | AV15: xml005_B00150
A16: 5 | B16: ID（社員番号等） | AH16: 全角文字列 | AI16: サマリ参照 | AJ16: 10 | AK16: 15 | AT16: 左 | AV16: xml005_M00070
A17: 6
A18: 7
A19: 明細領域
A20: 1 | B20: 提出に関する情報 | H20: 給与の支払者の名称 | AH20: 全角文字列 | AI20: サマリ参照 | AJ20: 10 | AK20: 30 | AT20: 左 | AV20: xml005_B00070
A21: 2 | B21: 提出に関する情報 | H21: 給与の支払者の法人番号 | AH21: 数値 | AI21: サマリ参照 | AJ21: 10 | AK21: 13 | AT21: 左 | AV21: xml005_B00080
A22: 3 | B22: 提出に関する情報 | H22: 給与の支払者の所在地 | AH22: 文字列 | AI22: サマリ参照 | AJ22: 10 | AK22: 100 | AT22: 左 | AV22: xml005_B00110 xml005_B00120 xml005_B00130
A23: 4 | B23: 提出に関する情報 | H23: フリガナ | AH23: 全角文字列 | AI23: サマリ参照 | AJ23: 10 | AK23: 60 | AT23: 左 | AV23: xml005_B00140
A24: 5 | B24: 提出に関する情報 | H24: 氏名 | AH24: 全角文字列 | AI24: サマリ参照 | AJ24: 10 | AK24: 30 | AT24: 左 | AV24: xml005_B00150
A25: 6 | B25: 提出に関する情報 | H25: 住所又は居所 | AH25: 文字列 | AI25: サマリ参照 | AJ25: 10 | AK25: 100 | AT25: 左 | AV25: xml005_B00180 xml005_B00190 xml005_B00200
A26: 7 | B26: 提出に関する情報 | H26: 世帯主の氏名 | AH26: 全角文字列 | AI26: サマリ参照 | AJ26: 10 | AK26: 30 | AT26: 左 | AV26: xml005_B00220
A27: 8 | B27: 提出に関する情報 | H27: 続柄 | AH27: 全角文字列 | AI27: サマリ参照 | AJ27: 10 | AK27: 10 | AT27: 左 | AV27: 【xml005_B00240がその他の時】 xml005_B00250 【それ以外】 xml005_B00240
A28: 9 | B28: 居住年月日情報 | H28: 新築等居住開始年月日 | AH28: 生年月日 | AI28: サマリ参照 | AJ28: 10 | AK28: 18 | AT28: 左 | AV28: xml005_C00020 xml005_C00030 xml005_C00040 xml005_C00050 xml005_C00060
A29: 10 | B29: 居住年月日情報 | H29: 増改築等居住開始年月日 | AH29: 生年月日 | AI29: サマリ参照 | AJ29: 10 | AK29: 18 | AT29: 左 | AV29: xml005_C00080 xml005_C00090 xml005_C00100 xml005_C00110 xml005_C00120
A30: 11 | B30: ①新築、購入及び増改築等に係る 住宅借入金等の年末残高 (内、連帯債務による借入金の額) | H30: A 住宅のみ | AH30: 金額 | AI30: サマリ参照 | AJ30: 10 | AK30: 15 | AM30: ○ | AO30: ○ | AT30: 右 | AV30: xml005_D00010 | AW30: 複数ある場合は合計
A31: 12 | H31: B 土地等のみ | AH31: 金額 | AI31: サマリ参照 | AJ31: 10 | AK31: 15 | AM31: ○ | AO31: ○ | AT31: 右 | AV31: xml005_D00020 | AW31: 複数ある場合は合計
A32: 13 | H32: C 住宅及び土地等 | AH32: 金額 | AI32: サマリ参照 | AJ32: 10 | AK32: 15 | AM32: ○ | AO32: ○ | AT32: 右 | AV32: xml005_D00030 | AW32: 複数ある場合は合計
A33: 14 | H33: D 増改築等に係る計算 | AH33: 金額 | AI33: サマリ参照 | AJ33: 10 | AK33: 15 | AM33: ○ | AO33: ○ | AT33: 右 | AV33: xml005_I00010 | AW33: 複数ある場合は合計
A34: 15 | B34: ②住宅借入金等の年末残高 (①のうち単独債務の額+ ①のうち連帯債務の額ﾗ 「連帯債務割合」) | H34: A 住宅のみ | AH34: 金額 | AI34: サマリ参照 | AJ34: 10 | AK34: 15 | AM34: ○ | AO34: ○ | AT34: 右 | AV34: xml005_G00010
A35: 16 | H35: B 土地等のみ | AH35: 金額 | AI35: サマリ参照 | AJ35: 10 | AK35: 15 | AM35: ○ | AO35: ○ | AT35: 右 | AV35: xml005_G00020
A36: 17 | H36: C 住宅及び土地等 | AH36: 金額 | AI36: サマリ参照 | AJ36: 10 | AK36: 15 | AM36: ○ | AO36: ○ | AT36: 右 | AV36: xml005_G00030
A37: 18 | H37: D 増改築等に係る計算 | AH37: 金額 | AI37: サマリ参照 | AJ37: 10 | AK37: 15 | AM37: ○ | AO37: ○ | AT37: 右 | AV37: xml005_I00070 | AW37: 複数ある場合は合計
A38: 19 | B38: ③②と証明事項の取得対価の額 又は増改築等の費用の額 のいずれが少ない方の金額 | H38: A 住宅のみ | AH38: 数値 | AI38: サマリ参照 | AJ38: 10 | AK38: 5 | AN38: 1 | AT38: 左 | AV38: 【②の方が少ない場合】 xml005_G00010 【取得対価の額の方が少ない場合】 xml005_E00010
A39: 20 | H39: B 土地等のみ | AH39: 数値 | AI39: サマリ参照 | AJ39: 10 | AK39: 5 | AN39: 1 | AT39: 左 | AV39: 【②の方が少ない場合】 xml005_G00020 【取得対価の額の方が少ない場合】 xml005_E00020
A40: 21 | H40: C 住宅及び土地等 | AH40: 数値 | AI40: サマリ参照 | AJ40: 10 | AK40: 5 | AN40: 1 | AT40: 左 | AV40: 【②の方が少ない場合】 xml005_G00030 【取得対価の額の方が少ない場合】 xml005_E00030
A41: 22 | H41: D 増改築等に係る計算 | AH41: 数値 | AI41: サマリ参照 | AJ41: 10 | AK41: 5 | AN41: 1 | AT41: 左 | AV41: 【②の方が少ない場合】 xml005_I00070 【増改築等の費用の額の方が少ない場合】 xml005_I00020
A42: 23 | B42: ④③×「居住用割合」 | H42: A 住宅のみ | AH42: 金額 | AI42: サマリ参照 | AJ42: 10 | AK42: 15 | AM42: ○ | AO42: ○ | AT42: 右 | AV42: xml005_H00010
...

Sheet 12_帳票項目定義
A1: ドキュメント名 | AH1: サブシステム名 | AO1: 版 | AP1: 日付 | AR1: 作成者
A2: =改版履歴!A2 -> 帳票設計書（PC/スマデバ共通） | AO2: 7 | AP2: 46217
A4: 帳票項目定義 | P4: 機能ID | AH4: 機能名 | AK4: 帳票ID | AO4: 帳票名
AH5: 共通機能 | AO5: 台紙PDF
P6: 明細行数 | AH6: ファイルID | AK6: ファイル名
AH7: daishiPDF | AK7: 台紙PDFファイル
A9: No. | B9: 項目名 | T9: 項目ID | AH9: 属性 | AI9: 文字指定 | AM9: 数値編集 | AQ9: 導出項目 | AR9: キー項目 | AS9: 印字 フォーマット | AT9: 配置 | AU9: 編集内容 | AV9: 申告書xml対応 | AW9: 備考 | BR9: チェック日付 | CF9: 確認
AI10: フォント名 | AJ10: フォント サイズ | AK10: 表示 文字数 | AL10: 装飾 | AM10: カンマ 編集 | AN10: 小数点 (桁) | AO10: 0表示 | AP10: 符号 | AQ10: 符号 | BR10: 属性 | BS10: フォント名 | BT10: フォント サイズ | BU10: 表示 文字数 | BV10: 装飾 | BW10: カンマ 編集 | BX10: 小数点(桁) | BY10: 0表示 | BZ10: 符号 | CA10: 導出項目 | CB10: キー項目 | CC10: 印字 フォーマット | CD10: 配置 | CE10: 編集内容
A11: ヘッダ領域(H)
A12: 1 | B12: 控除申告年分 帳票名 | AH12: 全角文字列 | AI12: サマリ参照 | AJ12: 12 | AK12: 40 | AL12: 太字 | AT12: 左 | AV12: xml001_B00030 xml001_B00040 | AW12: 表示文言：年号Y年分 証明書貼付台紙
A13: 2 | B13: フリガナ | AH13: 全角文字列 | AI13: サマリ参照 | AJ13: 10 | AK13: 60 | AT13: 左 | AV13: 【給与所得者の扶養控除等（異動）申告書を出力する場合】 xml001_B00150 【給与所得者の保険料控除申告書を出力する場合】 xml003_B00140 【給与所得者住宅借入金等特別控除申告書を出力する場合】 xml005_B00140
A14: 3 | B14: 氏名 | AH14: 全角文字列 | AI14: サマリ参照 | AJ14: 10 | AK14: 30 | AT14: 左 | AV14: 【給与所得者の扶養控除等（異動）申告書を出力する場合】 xml001_B00160 【給与所得者の保険料控除申告書を出力する場合】 xml003_B00150 【給与所得者住宅借入金等特別控除申告書を出力する場合】 xml005_B00150
A15: 4 | B15: ID（社員番号等） | AH15: 全角文字列 | AI15: サマリ参照 | AJ15: 10 | AK15: 15 | AT15: 左 | AV15: 【給与所得者の扶養控除等（異動）申告書を出力する場合】 xml001_F00070 【給与所得者の保険料控除申告書を出力する場合】 xml003_J00070 【給与所得者住宅借入金等特別控除申告書を出力する場合】 xml005_M00070
A16: 5
A17: 明細領域
A18: =ROW()-17 -> 1 | B18: 勤労学生の証明書（学生証の写しなど） | AH18: 文字列 | AI18: サマリ参照 | AJ18: 10 | AK18: 40 | AT18: 左 | AV18: xml001_B00610 | AW18: 勤労学生控除を受ける場合
A19: =ROW()-17 -> 2 | B19: 親族関係書類/送金関係書類 | AH19: 文字列 | AI19: サマリ参照 | AJ19: 10 | AK19: 40 | AT19: 左 | AV19: xml001_C00040 xml001_D00030 | AW19: 国外居住親族に係る扶養控除、配偶者控除又は障害者控除を受ける場合 2026/05/26 追記 扶養控除等（異動）申告書の本年分で入力された特定親族に対する添付書類がある場合
A20: =ROW()-17 -> 3 | B20: 留学ビザ等書類 | AH20: 文字列 | AI20: サマリ参照 | AJ20: 10 | AK20: 40 | AT20: 左 | AV20: xml001_C00040 xml001_D00030 | AW20: 国外居住親族に係る扶養控除、配偶者控除又は障害者控除を受ける場合で、 留学により国内に住所及び居所を有しなくなった者
A21: =ROW()-17 -> 4 | B21: 38万円以上の送金関係書類 | AH21: 文字列 | AI21: サマリ参照 | AJ21: 10 | AK21: 40 | AT21: 左 | AV21: xml001_C00040 xml001_D00030 | AW21: 国外居住親族に係る扶養控除、配偶者控除又は障害者控除を受ける場合で、 16歳以上の扶養親族
A22: =ROW()-17 -> 5 | B22: 保険会社名 | H22: 生命保険料控除証明書 | AH22: 文字列 | AI22: サマリ参照 | AJ22: 10 | AK22: 40 | AT22: 左 | AV22: xml003_C00020 xml003_C00130 | AW22: 保険料控除を受ける場合
A23: =ROW()-17 -> 6 | B23: 保険会社名 | H23: 介護保険料控除証明書 | AH23: 文字列 | AI23: サマリ参照 | AJ23: 10 | AK23: 40 | AT23: 左 | AV23: xml003_D00020 xml003_D00120 | AW23: 保険料控除を受ける場合
A24: =ROW()-17 -> 7 | B24: 保険会社名 | H24: 個人年金控除証明書 | AH24: 文字列 | AI24: サマリ参照 | AJ24: 10 | AK24: 40 | AT24: 左 | AV24: xml003_E00020 xml003_E00190 | AW24: 保険料控除を受ける場合
A25: =ROW()-17 -> 8 | B25: 保険会社名 | H25: 地震保険料控除証明書 | AH25: 文字列 | AI25: サマリ参照 | AJ25: 10 | AK25: 40 | AT25: 左 | AV25: xml003_G00020 xml003_G00130 | AW25: 保険料控除を受ける場合
A26: =ROW()-17 -> 9 | B26: 国民年金の保険料及び国民年金基金の掛金の証明書 | AH26: 文字列 | AI26: サマリ参照 | AJ26: 10 | AK26: 40 | AT26: 左 | AV26: xml003_H00080 | AW26: 国民年金の保険料及び国民年金基金の掛金について、社会保険料控除を受ける場合
A27: =ROW()-17 -> 10 | B27: 小規模企業共済等掛金払込証明書 | AH27: 文字列 | AI27: サマリ参照 | AJ27: 10 | AK27: 40 | AT27: 左 | AV27: xml003_I00010 xml003_I00020 xml003_I00030 xml003_I00040 | AW27: 小規模企業共済等掛金控除を受ける場合
A28: =ROW()-17 -> 11 | B28: 住宅借入金等特別控除証明書 | AH28: 文字列 | AI28: サマリ参照 | AJ28: 10 | AK28: 40 | AT28: 左 | AV28: - | AW28: 住宅借入金等特別控除証明書
A29: =ROW()-17 -> 12 | B29: 住宅取得資金に係る借入金の年末残高等証明書（調書方式を利用される場合は提出不要） | AH29: 文字列 | AI29: サマリ参照 | AJ29: 10 | AK29: 40 | AT29: 左 | AV29: - | AW29: 住宅ローン控除を受ける場合
A30: フッター領域(F)
A31: 1 | B31: フッタ無し
A32: 2
A33: 3
A34: 4
A35: 5
A36: 6
A37: 7
A38: 8

Sheet 13_帳票項目定義
A1: ドキュメント名 | AH1: サブシステム名 | AO1: 版 | AP1: 日付 | AR1: 作成者
A2: =改版履歴!A2 -> 帳票設計書（PC/スマデバ共通） | AO2: 4 | AP2: 45218
A4: 帳票項目定義 | P4: 機能ID | AH4: 機能名 | AK4: 帳票ID | AO4: 帳票名
AH5: 基礎控除申告書 | AO5: 基礎控除申告書PDF
P6: 明細行数 | AH6: ファイルID | AK6: ファイル名
AH7: kisokoujoPDF | AK7: 基礎控除申告書PDFファイル
A9: No. | B9: 項目名 | T9: 項目ID | AH9: 属性 | AI9: 文字指定 | AM9: 数値編集 | AQ9: 導出項目 | AR9: キー項目 | AS9: 印字 フォーマット | AT9: 配置 | AU9: 編集内容 | AV9: 備考 | BQ9: チェック日付 | CE9: 確認
AI10: フォント名 | AJ10: フォント サイズ | AK10: 表示 文字数 | AL10: 装飾 | AM10: カンマ 編集 | AN10: 小数点 (桁) | AO10: 0表示 | AP10: 符号 | AQ10: 符号 | BQ10: 属性 | BR10: フォント名 | BS10: フォント サイズ | BT10: 表示 文字数 | BU10: 装飾 | BV10: カンマ 編集 | BW10: 小数点(桁) | BX10: 0表示 | BY10: 符号 | BZ10: 導出項目 | CA10: キー項目 | CB10: 印字 フォーマット | CC10: 配置 | CD10: 編集内容
A11: ヘッダ領域(H)
A12: 1 | B12: 控除申告年分 帳票名 | AH12: 全角文字列 | AI12: サマリ参照 | AJ12: 12 | AK12: 40 | AL12: 太字 | AT12: 左
A13: 2 | B13: 所轄税務署 | AH13: 全角文字列 | AI13: サマリ参照 | AJ13: 12 | AK13: 10 | AL13: 太字 | AT13: 左
A14: 3 | B14: フリガナ | AH14: 全角文字列 | AI14: サマリ参照 | AJ14: 10 | AK14: 60 | AT14: 左
A15: 4 | B15: 氏名 | AH15: 全角文字列 | AI15: サマリ参照 | AJ15: 10 | AK15: 30 | AT15: 左
A16: 5 | B16: ID（社員番号等） | AH16: 全角文字列 | AI16: サマリ参照 | AJ16: 10 | AK16: 15 | AT16: 左
A17: 6
A18: 7
A19: 出力領域
A20: 1 | B20: 提出に関する情報 | H20: 給与の支払者の名称 | AH20: 全角文字列 | AI20: サマリ参照 | AJ20: 10 | AK20: 30 | AT20: 左
A21: 2 | B21: 提出に関する情報 | H21: 給与の支払者の法人番号 | AH21: 数値 | AI21: サマリ参照 | AJ21: 10 | AK21: 13 | AT21: 左
A22: 3 | B22: 提出に関する情報 | H22: 給与の支払者の所在地 | AH22: 文字列 | AI22: サマリ参照 | AJ22: 10 | AK22: 100 | AT22: 左
A23: 4 | B23: 提出に関する情報 | H23: フリガナ | AH23: 全角文字列 | AI23: サマリ参照 | AJ23: 10 | AK23: 60 | AT23: 左
A24: 5 | B24: 提出に関する情報 | H24: 氏名 | AH24: 全角文字列 | AI24: サマリ参照 | AJ24: 10 | AK24: 30 | AT24: 左
A25: 6 | B25: 提出に関する情報 | H25: 住所又は居所 | AH25: 文字列 | AI25: サマリ参照 | AJ25: 10 | AK25: 100 | AT25: 左
A26: 7 | B26: 合計所得の見積額 | H26: あなたの本年中の合計所得金額の見積額 | AH26: 金額 | AI26: サマリ参照 | AJ26: 10 | AK26: 15 | AM26: ○ | AO26: ○ | AT26: 右
A27: 8 | B27: 合計所得の見積額 | H27: 区分１ | AH27: 文字列 | AI27: サマリ参照 | AJ27: 10 | AK27: 30 | AT27: 左
A28: 9 | B28: 控除の計算 | H28: 基礎控除の額 | AH28: 金額 | AI28: サマリ参照 | AJ28: 10 | AK28: 8 | AL28: 太字 | AM28: ○ | AO28: ○ | AT28: 右
A29: 10 | B29: 参考情報 | H29: 提出年月日 | AH29: 年月日 | AI29: サマリ参照 | AJ29: 10 | AK29: 18 | AT29: 左
A30: 11 | B30: 参考情報 | H30: ID（社員番号等） | AH30: 文字列 | AI30: サマリ参照 | AJ30: 10 | AK30: 15 | AT30: 左
A31: フッター領域(F)
A32: 1 | B32: フッタ無し
A33: 2
A34: 3
A35: 4
A36: 5
A37: 6
A38: 7
A39: 8

Sheet 14_帳票項目定義
A1: ドキュメント名 | AH1: サブシステム名 | AO1: 版 | AP1: 日付 | AR1: 作成者
A2: =改版履歴!A2 -> 帳票設計書（PC/スマデバ共通） | AO2: 4 | AP2: 45218
A4: 帳票項目定義 | P4: 機能ID | AH4: 機能名 | AK4: 帳票ID | AO4: 帳票名
AH5: 所得金額調整控除申告書 | AO5: 所得金額調整控除申告書PDF
P6: 明細行数 | AH6: ファイルID | AK6: ファイル名
AH7: syotokuchoseikoujoPDF | AK7: 所得金額調整控除申告書PDFファイル
A9: No. | B9: 項目名 | T9: 項目ID | AH9: 属性 | AI9: 文字指定 | AM9: 数値編集 | AQ9: 導出項目 | AR9: キー項目 | AS9: 印字 フォーマット | AT9: 配置 | AU9: 編集内容 | AV9: 備考 | BQ9: チェック日付 | CE9: 確認
AI10: フォント名 | AJ10: フォント サイズ | AK10: 表示 文字数 | AL10: 装飾 | AM10: カンマ 編集 | AN10: 小数点 (桁) | AO10: 0表示 | AP10: 符号 | AQ10: 符号 | BQ10: 属性 | BR10: フォント名 | BS10: フォント サイズ | BT10: 表示 文字数 | BU10: 装飾 | BV10: カンマ 編集 | BW10: 小数点(桁) | BX10: 0表示 | BY10: 符号 | BZ10: 導出項目 | CA10: キー項目 | CB10: 印字 フォーマット | CC10: 配置 | CD10: 編集内容
A11: ヘッダ領域(H)
A12: 1 | B12: 控除申告年分 帳票名 | AH12: 全角文字列 | AI12: サマリ参照 | AJ12: 12 | AK12: 40 | AL12: 太字 | AT12: 左
A13: 2 | B13: 所轄税務署 | AH13: 全角文字列 | AI13: サマリ参照 | AJ13: 12 | AK13: 10 | AL13: 太字 | AT13: 左
A14: 3 | B14: フリガナ | AH14: 全角文字列 | AI14: サマリ参照 | AJ14: 10 | AK14: 60 | AT14: 左
A15: 4 | B15: 氏名 | AH15: 全角文字列 | AI15: サマリ参照 | AJ15: 10 | AK15: 30 | AT15: 左
A16: 5 | B16: ID（社員番号等） | AH16: 全角文字列 | AI16: サマリ参照 | AJ16: 10 | AK16: 15 | AT16: 左
A17: 6
A18: 7
A19: 出力領域
A20: 1 | B20: 提出に関する情報 | H20: 給与の支払者の名称 | AH20: 全角文字列 | AI20: サマリ参照 | AJ20: 10 | AK20: 30 | AT20: 左
A21: 2 | B21: 提出に関する情報 | H21: 給与の支払者の法人番号 | AH21: 数値 | AI21: サマリ参照 | AJ21: 10 | AK21: 13 | AT21: 左
A22: 3 | B22: 提出に関する情報 | H22: 給与の支払者の所在地 | AH22: 文字列 | AI22: サマリ参照 | AJ22: 10 | AK22: 100 | AT22: 左
A23: 4 | B23: 提出に関する情報 | H23: フリガナ | AH23: 全角文字列 | AI23: サマリ参照 | AJ23: 10 | AK23: 60 | AT23: 左
A24: 5 | B24: 提出に関する情報 | H24: 氏名 | AH24: 全角文字列 | AI24: サマリ参照 | AJ24: 10 | AK24: 30 | AT24: 左
A25: 6 | B25: 提出に関する情報 | H25: 住所又は居所 | AH25: 文字列 | AI25: サマリ参照 | AJ25: 10 | AK25: 100 | AT25: 左
A26: 7 | B26: 適用を受けようとする旨 | AH26: 全角文字列 | AI26: サマリ参照 | AJ26: 10 | AK26: 3 | AT26: 左
A27: 8 | B27: 申告の条件 | H27: 申告者が特別障害者である旨及びその該当する事実 | AH27: 全角文字列 | AI27: サマリ参照 | AJ27: 10 | AK27: 3 | AT27: 左 | AV27: XMLの以下の項目参照 「申告者が特別障害者である旨及びその該当する事実」がNULLでなければ「申告者本人が特別障害者」 「特別障害者である同一生計配偶者／扶養親族」がNULLでなくその「続柄」が配偶者なら「同一配偶者が特別障害者」 「特別障害者である同一生計配偶者／扶養親族」がNULLでなくその「続柄」が配偶者以外なら「扶養親族が特別障害者」 「23歳未満の扶養親族」がNULLでなければ「扶養親族が年齢23歳未満」
A28: 9 | B28: 申告の条件 | H28: 23歳未満の扶養親族 | N28: フリガナ | AH28: 全角文字列 | AI28: サマリ参照 | AJ28: 10 | AK28: 60 | AT28: 左
A29: 10 | B29: 申告の条件 | H29: 23歳未満の扶養親族 | N29: 氏名(続柄) | AH29: 全角文字列 | AI29: サマリ参照 | AJ29: 10 | AK29: 40 | AT29: 左
A30: 11 | B30: 申告の条件 | H30: 23歳未満の扶養親族 | N30: 個人番号 | AH30: 数値 | AI30: サマリ参照 | AJ30: 10 | AK30: 12 | AT30: 左
A31: 12 | B31: 申告の条件 | H31: 23歳未満の扶養親族 | N31: 生年月日 | AH31: 生年月日 | AI31: サマリ参照 | AJ31: 10 | AK31: 18 | AT31: 左
A32: 13 | B32: 申告の条件 | H32: 23歳未満の扶養親族 | N32: 本年中の所得の見積額 | AH32: 金額 | AI32: サマリ参照 | AJ32: 10 | AK32: 8 | AM32: ○ | AO32: ○ | AT32: 右
A33: 14 | B33: 申告の条件 | H33: 23歳未満の扶養親族 | N33: 住所又は居所 | AH33: 文字列 | AI33: サマリ参照 | AJ33: 10 | AK33: 100 | AT33: 左
A34: 15 | B34: 申告の条件 | H34: 特別障害者である同一生計配偶者／扶養親族 | N34: フリガナ | AH34: 全角文字列 | AI34: サマリ参照 | AJ34: 10 | AK34: 60 | AT34: 左
A35: 16 | B35: 申告の条件 | H35: 特別障害者である同一生計配偶者／扶養親族 | N35: 氏名(続柄) | AH35: 全角文字列 | AI35: サマリ参照 | AJ35: 10 | AK35: 40 | AT35: 左
A36: 17 | B36: 申告の条件 | H36: 特別障害者である同一生計配偶者／扶養親族 | N36: 個人番号 | AH36: 数値 | AI36: サマリ参照 | AJ36: 10 | AK36: 12 | AT36: 左
A37: 18 | B37: 申告の条件 | H37: 特別障害者である同一生計配偶者／扶養親族 | N37: 生年月日 | AH37: 生年月日 | AI37: サマリ参照 | AJ37: 10 | AK37: 18 | AT37: 左
A38: 19 | B38: 申告の条件 | H38: 特別障害者である同一生計配偶者／扶養親族 | N38: 本年中の所得の見積額 | AH38: 金額 | AI38: サマリ参照 | AJ38: 10 | AK38: 8 | AM38: ○ | AO38: ○ | AT38: 右
A39: 20 | B39: 申告の条件 | H39: 特別障害者である同一生計配偶者／扶養親族 | N39: 住所又は居所 | AH39: 文字列 | AI39: サマリ参照 | AJ39: 10 | AK39: 100 | AT39: 左
A40: 21 | B40: 申告の条件 | H40: 特別障害者である同一生計配偶者／扶養親族 | N40: 特別障害者に該当する旨及びその該当する事実 | AH40: 全角文字列 | AI40: サマリ参照 | AJ40: 10 | AK40: 3 | AT40: 左 | AV40: 手帳の種類及び交付年月日を記載
A41: 22 | B41: 参考情報 | H41: 提出年月日 | AH41: 年月日 | AI41: サマリ参照 | AJ41: 10 | AK41: 18 | AT41: 左
A42: 23 | B42: 参考情報 | H42: ID（社員番号等） | AH42: 文字列 | AI42: サマリ参照 | AJ42: 10 | AK42: 15 | AT42: 左
...

Sheet 15_帳票項目定義
A1: ドキュメント名 | AH1: サブシステム名 | AO1: 版 | AP1: 日付 | AR1: 作成者
A2: =改版履歴!A2 -> 帳票設計書（PC/スマデバ共通） | AO2: 6 | AP2: 45831
A4: 帳票項目定義 | P4: 機能ID | AH4: 機能名 | AK4: 帳票ID | AO4: 帳票名
AH5: 基礎控除申告書 兼 配偶者控除等申告書 兼 特定親族特別控除申告書 兼 所得金額調整控除申告書 | AO5: 基礎控除申告書 兼 配偶者控除等申告書 兼 特定親族特別控除申告書 兼 所得金額調整控除申告書PDF
P6: 明細行数 | AH6: ファイルID | AK6: ファイル名
AH7: kisohaiguchouseikoujoPDF | AK7: 基礎控除申告書兼配偶者控除等申告書兼特定親族特別控除申告書兼所得金額調整控除申告書PDFファイル
A9: No. | B9: 項目名 | T9: 項目ID | AH9: 属性 | AI9: 文字指定 | AM9: 数値編集 | AQ9: 導出項目 | AR9: キー項目 | AS9: 印字 フォーマット | AT9: 配置 | AU9: 編集内容 | AV9: 申告書xml対応 | AW9: 備考 | BR9: チェック日付 | CF9: 確認
AI10: フォント名 | AJ10: フォント サイズ | AK10: 表示 文字数 | AL10: 装飾 | AM10: カンマ 編集 | AN10: 小数点 (桁) | AO10: 0表示 | AP10: 符号 | AQ10: 符号 | BR10: 属性 | BS10: フォント名 | BT10: フォント サイズ | BU10: 表示 文字数 | BV10: 装飾 | BW10: カンマ 編集 | BX10: 小数点(桁) | BY10: 0表示 | BZ10: 符号 | CA10: 導出項目 | CB10: キー項目 | CC10: 印字 フォーマット | CD10: 配置 | CE10: 編集内容
A11: ヘッダ領域(H)
A12: 1 | B12: 控除申告年分 帳票名 | AH12: 全角文字列 | AI12: サマリ参照 | AJ12: 12 | AK12: 40 | AL12: 太字 | AT12: 左 | AV12: 【基礎控除申告書を作成した場合】 xml006_B00030 xml006_B00040 【基礎控除申告書は作成せず、配偶者控除等申告書を作成した場合】 xml004_B00030 xml004_B00040 【基礎控除申告書、配偶者控除等申告書を作成せず、所得金額調整控除申告書を作成した場合】 xml007_B00030 xml007_B00040 【基礎控除申告書、配偶者控除等申告書、所得金額調整控除申告書を作成せず、特定親族特別控除申告書を作成した場合】 xml008_B00030 xml008_B00040 | AW12: 表示文言：年号Y年分 基礎控除申告書 兼 配偶者控除等申告書 兼 特定親族特別控除申告書 兼 所得金額調整控除申告書
A13: 2 | B13: 所轄税務署 | AH13: 全角文字列 | AI13: サマリ参照 | AJ13: 12 | AK13: 10 | AL13: 太字 | AT13: 左 | AV13: 【基礎控除申告書を作成した場合】 xml006_B00050 【基礎控除申告書は作成せず、配偶者控除等申告書を作成した場合】 xml004_B00050 【基礎控除申告書、配偶者控除等申告書を作成せず、所得金額調整控除申告書を作成した場合】 xml007_B00050 【基礎控除申告書、配偶者控除等申告書、所得金額調整控除申告書を作成せず、特定親族特別控除申告書を作成した場合】 xml008_B00050
A14: 3 | B14: フリガナ | AH14: 全角文字列 | AI14: サマリ参照 | AJ14: 10 | AK14: 60 | AT14: 左 | AV14: 【基礎控除申告書を作成した場合】 xml006_B00140 【基礎控除申告書は作成せず、配偶者控除等申告書を作成した場合】 xml004_B00140 【基礎控除申告書、配偶者控除等申告書を作成せず、所得金額調整控除申告書を作成した場合】 xml007_B00140 【基礎控除申告書、配偶者控除等申告書、所得金額調整控除申告書を作成せず、特定親族特別控除申告書を作成した場合】 xml008_B00140
A15: 4 | B15: 氏名 | AH15: 全角文字列 | AI15: サマリ参照 | AJ15: 10 | AK15: 30 | AT15: 左 | AV15: 【基礎控除申告書を作成した場合】 xml006_B00150 【基礎控除申告書、配偶者控除等申告書を作成せず、所得金額調整控除申告書を作成した場合】 xml007_B00150 【基礎控除申告書、配偶者控除等申告書を作成せず、所得金額調整控除申告書を作成した場合】 xml007_B00150 【基礎控除申告書、配偶者控除等申告書、所得金額調整控除申告書を作成せず、特定親族特別控除申告書を作成した場合】 xml008_B00150
A16: 5 | B16: ID（社員番号等） | AH16: 全角文字列 | AI16: サマリ参照 | AJ16: 10 | AK16: 15 | AT16: 左 | AV16: 【基礎控除申告書を作成した場合】 xml006_E00070 【基礎控除申告書は作成せず、配偶者控除等申告書を作成した場合】 xml004_F00070 【基礎控除申告書、配偶者控除等申告書を作成せず、所得金額調整控除申告書を作成した場合】 xml007_D00070 【基礎控除申告書、配偶者控除等申告書、所得金額調整控除申告書を作成せず、特定親族特別控除申告書を作成した場合】 xml008_D00070
A17: 6
A18: 出力領域
A19: 1 | B19: 提出に関する情報 | H19: 所轄税務署長 | AH19: 全角文字列 | AI19: サマリ参照 | AJ19: 10 | AK19: 10 | AT19: 左 | AV19: 【基礎控除申告書を作成した場合】 xml006_B00050 【基礎控除申告書は作成せず、配偶者控除等申告書を作成した場合】 xml004_B00050 【基礎控除申告書、配偶者控除等申告書を作成せず、所得金額調整控除申告書を作成した場合】 xml007_B00050 【基礎控除申告書、配偶者控除等申告書、所得金額調整控除申告書を作成せず、特定親族特別控除申告書を作成した場合】 xml008_B00050
A20: 2 | B20: 提出に関する情報 | H20: 給与の支払者の名称(氏名) | AH20: 全角文字列 | AI20: サマリ参照 | AJ20: 10 | AK20: 30 | AT20: 左 | AV20: 【基礎控除申告書を作成した場合】 xml006_B00070 【基礎控除申告書は作成せず、配偶者控除等申告書を作成した場合】 xml004_B00070 【基礎控除申告書、配偶者控除等申告書を作成せず、所得金額調整控除申告書を作成した場合】 xml007_B00070 【基礎控除申告書、配偶者控除等申告書、所得金額調整控除申告書を作成せず、特定親族特別控除申告書を作成した場合】 xml008_B00070
A21: 3 | B21: 提出に関する情報 | H21: 給与の支払者の法人番号 | AH21: 数値 | AI21: サマリ参照 | AJ21: 10 | AK21: 13 | AT21: 左 | AV21: 【基礎控除申告書を作成した場合】 xml006_B00080 【基礎控除申告書は作成せず、配偶者控除等申告書を作成した場合】 xml004_B00080 【基礎控除申告書、配偶者控除等申告書を作成せず、所得金額調整控除申告書を作成した場合】 xml007_B00080 【基礎控除申告書、配偶者控除等申告書、所得金額調整控除申告書を作成せず、特定親族特別控除申告書を作成した場合】 xml008_B00080
A22: 4 | B22: 提出に関する情報 | H22: 給与の支払者の所在地(住所) | AH22: 文字列 | AI22: サマリ参照 | AJ22: 10 | AK22: 100 | AT22: 左 | AV22: 【基礎控除申告書を作成した場合】 xml006_B00110 xml006_B00120 xml006_B00130 【基礎控除申告書は作成せず、配偶者控除等申告書を作成した場合】 xml004_B00110 xml004_B00120 xml004_B00130 【基礎控除申告書、配偶者控除等申告書を作成せず、所得金額調整控除申告書を作成した場合】 xml007_B00110 xml007_B00120 xml007_B00130 【基礎控除申告書、配偶者控除等申告書、所得金額調整控除申告書を作成せず、特定親族特別控除申告書を作成した場合】 xml008_B00110 xml008_B00120 xml008_B00130
A23: 5 | B23: 提出に関する情報 | H23: (フリガナ) | AH23: 全角文字列 | AI23: サマリ参照 | AJ23: 10 | AK23: 60 | AT23: 左 | AV23: 【基礎控除申告書を作成した場合】 xml006_B00140 【基礎控除申告書は作成せず、配偶者控除等申告書を作成した場合】 xml004_B00140 【基礎控除申告書、配偶者控除等申告書を作成せず、所得金額調整控除申告書を作成した場合】 xml007_B00140 【基礎控除申告書、配偶者控除等申告書、所得金額調整控除申告書を作成せず、特定親族特別控除申告書を作成した場合】 xml008_B00140
A24: 6 | B24: 提出に関する情報 | H24: あなたの氏名 | AH24: 全角文字列 | AI24: サマリ参照 | AJ24: 10 | AK24: 30 | AT24: 左 | AV24: 【基礎控除申告書を作成した場合】 xml006_B00150 【基礎控除申告書は作成せず、配偶者控除等申告書を作成した場合】 xml004_B00150 【基礎控除申告書、配偶者控除等申告書を作成せず、所得金額調整控除申告書を作成した場合】 xml007_B00150 【基礎控除申告書、配偶者控除等申告書、所得金額調整控除申告書を作成せず、特定親族特別控除申告書を作成した場合】 xml008_B00150
A25: 7 | B25: 提出に関する情報 | H25: あなたの住所又は居所 | AH25: 文字列 | AI25: サマリ参照 | AJ25: 10 | AK25: 100 | AT25: 左 | AV25: 【基礎控除申告書を作成した場合】 xml006_B00180 xml006_B00190 xml006_B00200 【基礎控除申告書は作成せず、配偶者控除等申告書を作成した場合】 xml004_B00180 xml004_B00190 xml004_B00200 【基礎控除申告書、配偶者控除等申告書を作成せず、所得金額調整控除申告書を作成した場合】 xml007_B00180 xml007_B00190 xml007_B00200 【基礎控除申告書、配偶者控除等申告書、所得金額調整控除申告書を作成せず、特定親族特別控除申告書を作成した場合】 xml008_B00180 xml008_B00190 xml008_B00200
A26: 8 | B26: 給与所得者の基礎控除申告書 | H26: あなたの本年中の合計所得金額の見積額 | AH26: 金額 | AI26: サマリ参照 | AJ26: 10 | AK26: 15 | AM26: ○ | AO26: ○ | AT26: 右 | AV26: xml006_C00040
A27: 9 | B27: 給与所得者の基礎控除申告書 | H27: あなたの本年中の給与所得金額の見積額 | AH27: 金額 | AI27: サマリ参照 | AJ27: 10 | AK27: 15 | AM27: ○ | AO27: ○ | AT27: 右 | AV27: xml006_C00041
A28: 10 | B28: 給与所得者の基礎控除申告書 | H28: あなたの本年中の給与所得以外の所得金額の見積額 | AH28: 金額 | AI28: サマリ参照 | AJ28: 10 | AK28: 15 | AM28: ○ | AO28: ○ | AT28: 右 | AV28: xml006_C00042
A29: 11 | B29: 給与所得者の基礎控除申告書 | H29: 区分１ | AH29: 文字列 | AI29: サマリ参照 | AJ29: 10 | AK29: 30 | AT29: 左 | AV29: xml006_C00050
A30: 12 | B30: 給与所得者の基礎控除申告書 | H30: 基礎控除の額 | AH30: 金額 | AI30: サマリ参照 | AJ30: 10 | AK30: 8 | AL30: 太字 | AM30: ○ | AO30: ○ | AT30: 右 | AV30: xml006_D00010
A31: 13 | B31: 給与所得者の配偶者控除等申告書 | H31: (フリガナ) | AH31: 全角文字列 | AI31: サマリ参照 | AJ31: 10 | AK31: 60 | AT31: 左 | AV31: xml004_D00010
A32: 14 | B32: 給与所得者の配偶者控除等申告書 | H32: 配偶者の氏名 | AH32: 全角文字列 | AI32: サマリ参照 | AJ32: 10 | AK32: 30 | AT32: 左 | AV32: xml004_D00020
A33: 15 | B33: 給与所得者の配偶者控除等申告書 | H33: 配偶者の個人番号 | AH33: 文字列 | AI33: サマリ参照 | AJ33: 10 | AK33: 12 | AT33: 左 | AV33: xml004_D00030
A34: 16 | B34: 給与所得者の配偶者控除等申告書 | H34: 配偶者の生年月日 | AH34: 生年月日 | AI34: サマリ参照 | AJ34: 10 | AK34: 18 | AT34: 左 | AV34: xml004_D00050 xml004_D00060 xml004_D00070 xml004_D00080 xml004_D00090
A35: 17 | B35: 給与所得者の配偶者控除等申告書 | H35: あなたと配偶者の住所又は居所が異なる場合の配偶者の住所又は居所 | AH35: 全角文字列 | AI35: サマリ参照 | AJ35: 10 | AK35: 100 | AT35: 左 | AV35: xml004_D00130 xml004_D00140 xml004_D00150
A36: 18 | B36: 給与所得者の配偶者控除等申告書 | H36: 老人控除対象配偶者 | AH36: 全角文字列 | AI36: サマリ参照 | AJ36: 10 | AK36: 3 | AT36: 左 | AV36: xml004_D00160
A37: 19 | B37: 給与所得者の配偶者控除等申告書 | H37: 非居住者である配偶者 | AH37: 全角文字列 | AI37: サマリ参照 | AJ37: 10 | AK37: 3 | AT37: 左 | AV37: xml004_D00170
A38: 20 | B38: 給与所得者の配偶者控除等申告書 | H38: 生計を一にする事実 | AH38: 金額 | AI38: サマリ参照 | AJ38: 10 | AK38: 100 | AT38: 右 | AV38: 【xml004_D00210がその他の場合】 xml004_D00220 xml004_D00190 【それ以外】 xml004_D00210 xml004_D00190
A39: 21 | B39: 給与所得者の配偶者控除等申告書 | H39: 配偶者の本年中の合計所得金額の見積額 | AH39: 金額 | AI39: サマリ参照 | AJ39: 10 | AK39: 9 | AM39: ○ | AO39: ○ | AT39: 右 | AV39: xml004_D00260
A40: 22 | B40: 給与所得者の配偶者控除等申告書 | H40: 区分２ | AH40: 文字列 | AI40: サマリ参照 | AJ40: 10 | AK40: 30 | AT40: 左 | AV40: xml004_D00270
A41: 23 | B41: 給与所得者の配偶者控除等申告書 | H41: 配偶者控除の額 | AH41: 金額 | AI41: サマリ参照 | AJ41: 10 | AK41: 7 | AL41: 太字 | AM41: ○ | AO41: ○ | AT41: 右 | AV41: xml004_E00010
A42: 24 | B42: 給与所得者の配偶者控除等申告書 | H42: 配偶者特別控除の額 | AH42: 金額 | AI42: サマリ参照 | AJ42: 10 | AK42: 7 | AL42: 太字 | AM42: ○ | AO42: ○ | AT42: 右 | AV42: xml004_E00020
...

Sheet 16_帳票項目定義 
A1: ドキュメント名 | AH1: サブシステム名 | AO1: 版 | AP1: 日付 | AR1: 作成者
A2: =改版履歴!A2 -> 帳票設計書（PC/スマデバ共通） | AO2: 6 | AP2: 45824
A4: 帳票項目定義 | P4: 機能ID | AH4: 機能名 | AK4: 帳票ID | AO4: 帳票名
AH5: 控除額等一覧表PDF | AK5: PDF16 | AO5: 控除額等一覧表PDF
P6: 明細行数 | AH6: ファイルID | AK6: ファイル名
AH7: koujogakuichiranPDF | AK7: 控除額等一覧表PDFファイル
A9: No. | B9: 項目名 | T9: 項目ID | AH9: 属性 | AI9: 文字指定 | AM9: 数値編集 | AQ9: 導出項目 | AR9: キー項目 | AS9: 印字 フォーマット | AT9: 配置 | AU9: 編集内容 | AV9: ストレージ対応 | AW9: 備考
AI10: フォント名 | AJ10: フォント サイズ | AK10: 表示 文字数 | AL10: 装飾 | AM10: カンマ 編集 | AN10: 小数点 (桁) | AO10: 0表示 | AP10: 符号 | AQ10: 符号
A11: ヘッダ領域(H)
A12: 1 | B12: 帳票名 | AH12: 全角文字列 | AI12: サマリ参照 | AJ12: 12 | AK12: 40 | AL12: 太字 | AT12: 左 | AV12: -
A13: 出力領域
A14: 1 | B14: 所得見積額 | H14: 給与収入(見積額) | AH14: 金額 | AI14: サマリ参照 | AJ14: 10 | AK14: 15 | AM14: ○ | AO14: ○ | AT14: 左 | AV14: v001_054
A15: 2 | B15: 所得見積額 | H15: 所得金額調整控除額 | AH15: 金額 | AI15: サマリ参照 | AJ15: 10 | AK15: 15 | AM15: ○ | AO15: ○ | AT15: 左 | AV15: -※自動計算
A16: 3 | B16: 所得見積額 | H16: 給与所得金額（見積額） | AH16: 金額 | AI16: サマリ参照 | AJ16: 10 | AK16: 15 | AM16: ○ | AO16: ○ | AT16: 左 | AV16: v001_055
A17: 4 | B17: 所得見積額 | H17: 給与所得以外の所得（見積額） | AH17: 金額 | AI17: サマリ参照 | AJ17: 10 | AK17: 15 | AM17: ○ | AO17: ○ | AT17: 左 | AV17: v001_056
A18: 5 | B18: 所得見積額 | H18: 合計所得金額（見積額） | AH18: 金額 | AI18: サマリ参照 | AJ18: 10 | AK18: 15 | AM18: ○ | AO18: ○ | AT18: 左 | AV18: -※自動計算
A19: 6 | B19: 控除額 | H19: 社会保険料等控除額 | N19: 申告による社会保険料の控除分 | AH19: 金額 | AI19: サマリ参照 | AJ19: 10 | AK19: 15 | AM19: ○ | AO19: ○ | AT19: 左 | AV19: v008_008
A20: 7 | B20: 控除額 | H20: 社会保険料等控除額 | N20: ⑬うち国民年金保険料等の金額 | AH20: 金額 | AI20: サマリ参照 | AJ20: 10 | AK20: 15 | AM20: ○ | AO20: ○ | AT20: 左 | AV20: v008_007
A21: 8 | B21: 控除額 | H21: 社会保険料等控除額 | N21: 申告による小規模企業共済等掛金の控除分 | AH21: 金額 | AI21: サマリ参照 | AJ21: 10 | AK21: 15 | AM21: ○ | AO21: ○ | AT21: 左 | AV21: v009_005
A22: 9 | B22: 控除額 | H22: 生命保険料の控除額 | AH22: 金額 | AI22: サマリ参照 | AJ22: 10 | AK22: 15 | AM22: ○ | AO22: ○ | AT22: 左 | AV22: v006_016
A23: 10 | B23: 控除額 | H23: 生命保険料の控除額 | N23: 一般（旧制度） | AH23: 金額 | AI23: サマリ参照 | AJ23: 10 | AK23: 15 | AM23: ○ | AT23: 左 | AV23: -※自動計算
A24: 11 | B24: 控除額 | H24: 生命保険料の控除額 | N24: 一般（新制度） | AH24: 金額 | AI24: サマリ参照 | AJ24: 10 | AK24: 15 | AM24: ○ | AT24: 左 | AV24: -※自動計算
A25: 12 | B25: 控除額 | H25: 生命保険料の控除額 | N25: 介護医療保険 | AH25: 金額 | AI25: サマリ参照 | AJ25: 10 | AK25: 15 | AM25: ○ | AT25: 左 | AV25: -※自動計算
A26: 13 | B26: 控除額 | H26: 生命保険料の控除額 | N26: 個人年金（旧制度） | AH26: 金額 | AI26: サマリ参照 | AJ26: 10 | AK26: 15 | AM26: ○ | AT26: 左 | AV26: -※自動計算
A27: 14 | B27: 控除額 | H27: 生命保険料の控除額 | N27: 個人年金（新制度） | AH27: 金額 | AI27: サマリ参照 | AJ27: 10 | AK27: 15 | AM27: ○ | AT27: 左 | AV27: -※自動計算
A28: 15 | B28: 控除額 | H28: 地震保険料の控除額 | AH28: 金額 | AI28: サマリ参照 | AJ28: 10 | AK28: 15 | AM28: ○ | AO28: ○ | AT28: 左 | AV28: v007_015
A29: 16 | B29: 控除額 | H29: 配偶者（特別）控除額 | AH29: 金額 | AI29: サマリ参照 | AJ29: 10 | AK29: 7 | AM29: ○ | AO29: ○ | AT29: 左 | AV29: 【配偶者控除の額がない場合】 v003_024 【配偶者控除の額がある場合】 v003_023
A30: 17 | B30: 控除額 | H30: 配偶者（特別）控除額 | N30: 配偶者の所得金額 | AH30: 金額 | AI30: サマリ参照 | AJ30: 10 | AK30: 7 | AM30: ○ | AO30: ○ | AT30: 左 | AV30: v003_011
A31: 18 | B31: 控除額 | H31: 特定親族特別控除の額 | AH31: 金額 | AI31: サマリ参照 | AJ31: 10 | AK31: 7 | AM31: ○ | AO31: ○ | AT31: 左 | AV31: -※自動計算
A32: 19 | B32: 控除額 | H32: 特定親族特別控除の額 | N32: 該当となる親族 | AH32: 数値 | AI32: サマリ参照 | AJ32: 10 | AK32: 3 | AO32: ○ | AT32: 左 | AV32: -※自動計算
A33: 20 | B33: 控除額 | H33: 扶養控除額及び障害者等の控除額の合計額 | AH33: 金額 | AI33: サマリ参照 | AJ33: 10 | AK33: 15 | AM33: ○ | AO33: ○ | AT33: 左 | AV33: -※自動計算
A34: 21 | B34: 控除額 | H34: 扶養控除額及び障害者等の控除額の合計額 | N34: 扶養控除額 | AH34: 金額 | AI34: サマリ参照 | AJ34: 10 | AK34: 15 | AM34: ○ | AO34: ○ | AT34: 左 | AV34: -※自動計算
A35: 22 | B35: 控除額 | H35: 扶養控除額及び障害者等の控除額の合計額 | N35: 該当となる親族 | AH35: 数値 | AI35: サマリ参照 | AJ35: 10 | AK35: 3 | AO35: ○ | AT35: 左 | AV35: -※自動計算
A36: 23 | B36: 控除額 | H36: 扶養控除額及び障害者等の控除額の合計額 | N36: 障害者控除額 | AH36: 金額 | AI36: サマリ参照 | AJ36: 10 | AK36: 15 | AM36: ○ | AO36: ○ | AT36: 左 | AV36: -※自動計算
A37: 24 | B37: 控除額 | H37: 扶養控除額及び障害者等の控除額の合計額 | N37: 該当者 | AH37: 数値 | AI37: サマリ参照 | AJ37: 10 | AK37: 3 | AO37: ○ | AT37: 左 | AV37: -※自動計算
A38: 25 | B38: 控除額 | H38: 扶養控除額及び障害者等の控除額の合計額 | N38: 寡婦（夫）控除額 | AH38: 金額 | AI38: サマリ参照 | AJ38: 10 | AK38: 15 | AM38: ○ | AO38: ○ | AT38: 左 | AV38: -※自動計算
A39: 26 | B39: 控除額 | H39: 扶養控除額及び障害者等の控除額の合計額 | N39: ひとり親控除額 | AH39: 金額 | AI39: サマリ参照 | AJ39: 10 | AK39: 15 | AM39: ○ | AO39: ○ | AT39: 左 | AV39: -※自動計算
A40: 27 | B40: 控除額 | H40: 扶養控除額及び障害者等の控除額の合計額 | N40: 勤労学生控除額 | AH40: 金額 | AI40: サマリ参照 | AJ40: 10 | AK40: 15 | AM40: ○ | AO40: ○ | AT40: 左 | AV40: -※自動計算
A41: 28 | B41: 控除額 | H41: 基礎控除額 | AH41: 金額 | AI41: サマリ参照 | AJ41: 10 | AK41: 8 | AM41: ○ | AT41: 左 | AV41: v010_001
A42: 29 | B42: 控除額 | H42: 住宅借入金等特別控除額 | AH42: 金額 | AI42: サマリ参照 | AJ42: 10 | AK42: 5 | AM42: ○ | AT42: 左 | AV42: v012_017
...

Sheet パラメータ
A2: バージョン | F2: 1.1
A4: ジェネレータバージョン
A6: SDE対応バージョン | F6: Ver | G6: 9.4 | J6: ～ | K6: Ver | L6: 9.4
